Workbook

Sheet ① 작업표
A1: 연번 | B1: 장 | C1: 절·위치 | D1: 우선순위 | E1: 확인 항목 (마커 원문) | F1: 확인해야 할 조문·출처 | G1: 확인 내용 (체크리스트) | H1: 원고 위치 | I1: 상태 | J1: 확인 결과 기재란 | K1: 근거 URL·법령버전 | L1: 확인자 | M1: 확인일 | N1: 비고 | O1: 키 | P1: 자동판정
A2: 1 | B2: 1 | C2: 1.3 실무 절차 — 언제까지, 어디에 | D2: 🟡 중요 | E2: [검증필요: 시행령 §78① 원문 대조] | F2: 시행령 §78① | G2: 법정결정기한(상속세 신고기한부터 9개월, 증여세 6개월)의 근거 시행령 §78① 원문 대조. 현재 복수 2차 출처만 일치. | H2: 01_상속증여와_세금_전체그림.md L93 | I2: 미확인 | O2: 1|L0093|1 | P2: 미확인
A3: 2 | B3: 1 | C3: 1.4 누가 이 세금을 내는가 | D3: 🟢 보완 | E3: [검증필요 — 연도별 과세인원 절대 수치와 2021·2022년 과세 비율은 국세통계 인용 보도 경유. 국세통계포털(TASIS) 원문 대조 필요. 과세 비율 약 5.9%는 복수 출처 일치] | G3: 연도별 과세인원 절대 수치(2024년 피상속인 약 35만 9천 명 중 2만 1천여 명)와 2021·2022년 과세 비율이 국세통계 인용 보도 경유. 국세통계포털(TASIS) 원문 대조 필요. 과세 비율 약 5.9%는 복수 출처 일치. | H3: 01_상속증여와_세금_전체그림.md L155 | I3: 미확인 | O3: 1|L0155|1 | P3: 미확인
A4: 3 | B4: 1 | C4: 1.4 누가 이 세금을 내는가 | D4: 🟢 보완 | E4: [검증필요 — 기초·일괄공제 금액의 최종 개정 연도] | G4: "세율도 공제액도 그대로"의 근거인 기초·일괄공제 금액의 최종 개정 연도 확정. | H4: 01_상속증여와_세금_전체그림.md L159 | I4: 미확인 | O4: 1|L0159|1 | P4: 미확인
A5: 4 | B5: 1 | C5: 1.7 이 책 사용법 | D5: ⚪ 표기 | E5: [검증필요] | G5: 독자 유형별 읽기 안내표의 "[검증필요] 목록을 중심에 둔다" | H5: 01_상속증여와_세금_전체그림.md L219 | I5: 해당없음 | N5: 표기 설명·상호참조 — 원문 조회 대상 아님. 마커를 지우지 말 것 | O5: 1|L0219|1 | P5: 해당없음
A6: 5 | B6: 1 | C6: 1.7 이 책 사용법 | D6: ⚪ 표기 | E6: [검증필요] | G6: 표기 정의: "[검증필요] = 저자가 법령 원문과의 1:1 대조를 끝내지 못한 지점" | H6: 01_상속증여와_세금_전체그림.md L241 | I6: 해당없음 | N6: 표기 설명·상호참조 — 원문 조회 대상 아님. 마커를 지우지 말 것 | O6: 1|L0241|1 | P6: 해당없음
A7: 6 | B7: 1 | C7: 1.7 이 책 사용법 | D7: ⚪ 표기 | E7: [검증필요] | G7: 면책 박스의 "금액 기준과 [검증필요] 표기 항목은 인용 전 현행본 대조가 필요하다" | H7: 01_상속증여와_세금_전체그림.md L244 | I7: 해당없음 | N7: 표기 설명·상호참조 — 원문 조회 대상 아님. 마커를 지우지 말 것 | O7: 1|L0244|1 | P7: 해당없음
A8: 7 | B8: 1 | C8: 1.9 핵심 체크리스트 | D8: ⚪ 표기 | E8: [검증필요] | G8: "이 책의 표기와 면책의 의미를 확인했는가?" | H8: 01_상속증여와_세금_전체그림.md L273 | I8: 해당없음 | N8: 표기 설명·상호참조 — 원문 조회 대상 아님. 마커를 지우지 말 것 | O8: 1|L0273|1 | P8: 해당없음
A9: 8 | B9: 2 | C9: 2.1 국세청 해석은 법이 아니다 | D9: 🟢 보완 | E9: [검증필요 — 인용한 예규 2건(사전-2023-법규재산-0247, 사전-2025-법규재산-0190)은 2차 출처 경유이며 국세법령정보시스템 원문 대조 미실시] | F9: 사전-2023-법규재산-0247 · 사전-2025-법규재산-0190 | G9: 인용 예규 2건(사전-2023-법규재산-0247, 사전-2025-법규재산-0190)이 2차 출처 경유. 국세법령정보시스템 원문 대조 미실시. ※ 10장 L249와 동일 예규 — 함께 처리. | H9: 02_상증세법의_구조와_법령체계.md L50 | I9: 미확인 | N9: ※ 10장 L249와 동일 예규 — 함께 처리 | O9: 2|L0050|1 | P9: 미확인
A10: 9 | B10: 2 | C10: 2.2 조문 지도 | D10: 🟡 중요 | E10: [검증필요: 제6장 제목·범위 원문] | F10: §76 | G10: 상증세법 제6장의 제목·범위 원문 확인(현재 "보칙 §76~ 결정·경정·사후관리"로 표기). | H10: 02_상증세법의_구조와_법령체계.md L61 | I10: 미확인 | O10: 2|L0061|1 | P10: 미확인
A11: 10 | B11: 2 | C11: 2.3 조문 확인법 | D11: ⚪ 표기 | E11: [검증필요] | G11: "각 장 끝 [검증필요] 항목과 부록의 체크리스트" | H11: 02_상증세법의_구조와_법령체계.md L118 | I11: 해당없음 | N11: 표기 설명·상호참조 — 원문 조회 대상 아님. 마커를 지우지 말 것 | O11: 2|L0118|1 | P11: 해당없음
A12: 11 | B12: 2 | C12: 2.3 조문을 직접 확인하는 법 | D12: 🟢 보완 | E12: [검증필요 — 오픈API 이용 신청 절차와 요청 파라미터(인증용 ID 등)의 현행 사양은 이용 시점에 재확인 필요] | G12: law.go.kr 오픈API 이용 신청 절차와 요청 파라미터(인증용 ID 등)의 현행 사양은 이용 시점 재확인. ※ 부록 J L407과 동일 건. | H12: 02_상증세법의_구조와_법령체계.md L138 | I12: 미확인 | N12: ※ 부록 J L407과 동일 건 | O12: 2|L0138|1 | P12: 미확인
A13: 12 | B13: 3 | C13: 3.1 세법이 민법 위에 서 있다 | D13: 🟡 중요 | E13: [검증필요 — 특별수익·기여분의 근거 조문·산정 방식] | F13: 민법 §1008 · §1008의2 | G13: 특별수익·기여분의 근거 조문(민법 §1008·§1008의2 추정)과 산정 방식. ※ L193과 동일 쟁점 — 묶어서 처리. | H13: 03_상속의_민법_기초.md L46 | I13: 미확인 | N13: ※ L193과 동일 쟁점 — 묶어서 처리 | O13: 3|L0046|1 | P13: 미확인
A14: 13 | B14: 3 | C14: 3.2 3개월의 갈림길 (§1019) | D14: 🟡 중요 | E14: [검증필요 — 숙려기간 연장 청구의 근거 조문·요건] | G14: 숙려기간 연장 청구의 근거 조문·요건(가정법원 청구). | H14: 03_상속의_민법_기초.md L60 | I14: 미확인 | O14: 3|L0060|1 | P14: 미확인
A15: 14 | B15: 3 | C15: 3.3 격변기의 유류분 | D15: 🔴 최우선 | E15: [검증필요 — 산입 증여의 범위·기간 요건, 반환 순서의 근거 조문, 유류분 반환청구권의 행사 기간] | G15: ① 산입 증여의 범위·기간 요건(상속인 vs 제3자 구분) ② 반환 순서의 근거 조문(유증 우선 여부) ③ 유류분 반환청구권의 행사 기간. 세 가지 모두 유류분 계산 결과를 바꾸는 수치·순서다. | H15: 03_상속의_민법_기초.md L91 | I15: 미확인 | O15: 3|L0091|1 | P15: 미확인
A16: 15 | B16: 3 | C16: 3.3 격변기의 유류분 | D16: 🟡 중요 | E16: [검증필요: 법률번호·조문 원문 대조] | G16: 2026.2. 민법 개정의 법률번호·조문 원문 대조. 현재 근거가 "복수 로펌 출처"뿐. 골자 3가지(유류분 상실 사유 신설 / 기여 대가 증여의 산정 제외 / 가액 반환 원칙화)를 조문으로 확인. | H16: 03_상속의_민법_기초.md L97 | I16: 미확인 | O16: 3|L0097|1 | P16: 미확인
A17: 16 | B17: 3 | C17: 3.3 상속권 상실 제도 (민법 §1004의2) | D17: 🟡 중요 | E17: [검증필요: 상실자의 자녀 대습상속 처리 — 2026.2. 개정과 연동] | G17: 상실자의 자녀에 대한 대습상속 처리 — 2026.2. 개정과 연동해 확인. | H17: 03_상속의_민법_기초.md L99 | I17: 미확인 | O17: 3|L0099|1 | P17: 미확인
A18: 17 | B18: 3 | C18: 3.4 상속재산 분할 | D18: 🟢 보완 | E18: [검증필요 — 특별대리인 선임의 근거 조문·절차] | G18: 특별대리인 선임의 근거 조문·절차(미성년 상속인과 친권자의 이해상반). | H18: 03_상속의_민법_기초.md L113 | I18: 미확인 | O18: 3|L0113|1 | P18: 미확인
A19: 18 | B19: 3 | C19: 3.4 상속재산 분할 | D19: 🟡 중요 | E19: [검증필요 — 신고기한 내 재분할의 증여 제외 요건·근거 조문] | G19: 신고기한 내 재분할의 증여 제외 요건·근거 조문. 실무 조언의 근거가 되는 핵심 조문이므로 우선 확인. | H19: 03_상속의_민법_기초.md L119 | I19: 미확인 | O19: 3|L0119|1 | P19: 미확인
A20: 19 | B20: 3 | C20: 사례 3-3 | D20: ⚪ 표기 | E20: [검증필요] | G20: 사례 주석의 상호참조("산입 증여의 범위는 [검증필요] 항목입니다") → 실체는 3장 L91 | H20: 03_상속의_민법_기초.md L154 | I20: 해당없음 | N20: 표기 설명·상호참조 — 원문 조회 대상 아님. 마커를 지우지 말 것 | O20: 3|L0154|1 | P20: 해당없음
A21: 20 | B21: 3 | C21: 3.6 자주 묻는 질문 | D21: 🟢 보완 | E21: [검증필요 — 사실혼 배우자의 재산분할청구·이혼 소송 중 사망의 처리] | G21: 사실혼 배우자의 재산분할청구권 / 이혼 소송 중 사망의 처리. | H21: 03_상속의_민법_기초.md L187 | I21: 미확인 | O21: 3|L0187|1 | P21: 미확인
A22: 21 | B22: 3 | C22: 3.6 자주 묻는 질문 | D22: 🟡 중요 | E22: [검증필요 — 태아의 상속능력 근거 조문·출생 전 분할의 효력] | F22: 민법 §1000③ | G22: 태아의 상속능력 근거 조문(민법 §1000③ 추정)과 출생 전 분할의 효력. | H22: 03_상속의_민법_기초.md L190 | I22: 미확인 | O22: 3|L0190|1 | P22: 미확인
A23: 22 | B23: 3 | C23: 3.6 자주 묻는 질문 | D23: 🟡 중요 | E23: [검증필요 — 기여분의 근거 조문·산정 방식] | G23: 기여분의 근거 조문·산정 방식. ※ L46과 동일 쟁점. | H23: 03_상속의_민법_기초.md L193 | I23: 미확인 | N23: ※ L46과 동일 쟁점 | O23: 3|L0193|1 | P23: 미확인
A24: 23 | B24: 4 | C24: 4.2 납세의무자 (법 §3의2) | D24: 🟡 중요 | E24: [검증필요 — 제3조의2제2항 개정 전후 문언 대비, "지분상당액" 산정의 시행령 산식, 개정 법률 호수·공포일. law.go.kr 현행본 및 부칙 원문 1:1 대조 필요] | F24: §3의2 | G24: §3의2제2항 개정 전후 문언 대비, 개정 법률 호수·공포일. law.go.kr 현행본 및 부칙 원문 1:1 대조. (2026.1.1. 시행, 시행 이후 상속개시분 적용) | H24: 04_과세대상과_납세의무자.md L59 | I24: 미확인 | O24: 4|L0059|1 | P24: 미확인
A25: 24 | B25: 4 | C25: 4.2 납세의무자 | D25: 🟡 중요 | E25: [검증필요 — "받았거나 받을 재산"의 시행령상 정의 조문번호와 문언] | G25: 연대납부 한도의 "받았거나 받을 재산"의 시행령상 정의 조문번호와 문언. | H25: 04_과세대상과_납세의무자.md L71 | I25: 미확인 | O25: 4|L0071|1 | P25: 미확인
A26: 25 | B26: 4 | C26: 4.3 성립과 확정 | D26: 🟡 중요 | E26: [검증필요 — 납세의무 성립시기를 정한 국세기본법 조문번호·항호] | F26: 국기법 §21 | G26: 납세의무 성립시기를 정한 국세기본법 조문번호·항호(국기법 §21 추정). | H26: 04_과세대상과_납세의무자.md L79 | I26: 미확인 | O26: 4|L0079|1 | P26: 미확인
A27: 26 | B27: 4 | C27: 4.3 거주자 판정 | D27: 🔴 최우선 | E27: [검증필요: 원문 확인 전 확정 서술 금지] | G27: 2026년 귀속부터의 소득세법령 거주자 판정 개정("두 과세기간에 걸쳐 계속 183일 체류")이 상증세법 준용에 영향을 주는지. 원고에 "원문 확인 전 확정 서술 금지"로 명시됨 — 거주자 판정은 과세 범위 전체를 가르므로 최우선. ※ 13장 L50과 연동. | H27: 04_과세대상과_납세의무자.md L98 | I27: 미확인 | N27: ※ 13장 L50과 연동 | O27: 4|L0098|1 | P27: 미확인
A28: 27 | B28: 4 | C28: 4.5 자주 묻는 질문 | D28: 🟡 중요 | E28: [검증필요 — 상증세법상 실종선고 시 상속개시일 규정의 조문번호·문언, 민법상 사망 간주 시점과의 관계] | G28: 상증세법상 실종선고 시 상속개시일 규정의 조문번호·문언, 민법상 사망 간주 시점(실종기간 만료)과의 관계. 두 시점 사이에 수년의 간격이 생기고 적용 법령·평가기준일·합산 기산점을 한꺼번에 정하므로 실무 영향 큼. | H28: 04_과세대상과_납세의무자.md L158 | I28: 미확인 | O28: 4|L0158|1 | P28: 미확인
A29: 28 | B29: 4 | C29: 4.5 자주 묻는 질문 | D29: 🟡 중요 | E29: [검증필요 — 동시사망 추정의 민법 조문번호, 상속세 실무상 처리 근거] | F29: §30 | G29: 동시사망 추정의 민법 조문번호(§30 추정), 상속세 실무상 처리 근거. | H29: 04_과세대상과_납세의무자.md L161 | I29: 미확인 | O29: 4|L0161|1 | P29: 미확인
A30: 29 | B30: 4 | C30: 4.5 자주 묻는 질문 | D30: 🔴 최우선 | E30: [검증필요 — 지분상당액 산정 시행령 산식] | G30: 영리법인 주주 과세의 "지분상당액" 산정 시행령 산식. 세액을 직접 결정하는 산식. ※ L59와 함께 처리. | H30: 04_과세대상과_납세의무자.md L164 | I30: 미확인 | N30: ※ L59와 함께 처리 | O30: 4|L0164|1 | P30: 미확인
A31: 30 | B31: 5 | C31: 5.2 간주상속재산 3종 | D31: 🔴 최우선 | E31: [검증필요: 보험료 분담 시 안분 산식과 그 시행령 조항] | F31: 시행령 §4① | G31: 보험료 분담 시 안분 산식과 시행령 조항. → ✅ 검증 완료: 근거는 시행령 §4①(지급 보험금 총액 × 피상속인 부담 보험료 ÷ 사망 시까지 납입 보험료 총액). 출처 verify_상속재산_상속공제_원문대조.md 상속재산 6. 남은 작업은 원고 마커 삭제 + 출처 각주. | H31: 05_상속재산의_범위.md L54 | I31: 확인완료 | N31: verify_*.md 원문대조로 확정 — 남은 작업은 원고 마커 삭제 + 출처 각주 | O31: 5|L0054|1 | P31: 확인완료
A32: 31 | B32: 5 | C32: 5.2 간주상속재산 3종 | D32: 🟡 중요 | E32: [검증필요: §10 각 호 전체 열거 항목·근거 법률명 원문 대조] | F32: §10 | G32: §10 각 호 전체 열거 항목·근거 법률명 원문 대조. → 부분 확인: 제2·3호에 「공무원 재해보상법」·「군인 재해보상법」이 추가(2018.3.20)된 사실은 확정. 나머지 각 호의 전체 열거는 미확정 — 유지. | H32: 05_상속재산의_범위.md L58 | I32: 확인중 | N32: verify로 근거 일부 확보, 항목은 유지 | O32: 5|L0058|1 | P32: 확인중
A33: 32 | B33: 5 | C33: 5.3 추정상속재산 (법 §15) | D33: 🔴 최우선 | E33: [검증필요: 시행령 §11④ 축자 원문 1:1 대조 — 항·호 표기 포함] | F33: 시행령 §11④ · §11① · §11⑤ | G33: 시행령 §11④ 축자 원문 1:1 대조. → ✅ 검증 완료: 미소명액이 Min(처분·인출액×20%, 2억) 미만이면 전액 배제, 이상이면 그 적은 금액을 차감한 나머지 산입. 출처 동 파일 상속재산 3. 함께 확인: 3분류 근거는 §11①이 아니라 §11⑤이고 기타재산은 제4호(3호는 삭제). | H33: 05_상속재산의_범위.md L93 | I33: 확인완료 | N33: verify_*.md 원문대조로 확정 — 남은 작업은 원고 마커 삭제 + 출처 각주 | O33: 5|L0093|1 | P33: 확인완료
A34: 33 | B34: 5 | C34: 5.4 소명 실무 | D34: 🟢 보완 | E34: [검증필요: 조사 실무상 금융거래 조회의 기간·근거 규정] | F34: 법 §83 · 금융실명법 §4①2호 · §4⑥5호 · 사무처리규정 §36 | G34: 금융거래 조회의 기간·근거 규정. → 부분 확인: 근거 3단(법 §83 → 금융실명법 §4①2호·§4⑥5호 → 사무처리규정 §36)은 확정. "10년" 조회 관행의 법적 근거는 법령·훈령에 없음(실무 관행 추정) — 유지. 원고가 "10년"을 단정하지 않는지 확인. | H34: 05_상속재산의_범위.md L101 | I34: 확인중 | N34: verify로 근거 일부 확보, 항목은 유지 | O34: 5|L0101|1 | P34: 확인중
A35: 34 | B35: 5 | C35: 5.5 판례·사례 | D35: 🟢 보완 | E35: [검증필요: 판결 원문 대조] | G35: 사망 무렵 예금 대량 인출 사안의 판결 원문 대조(증명책임 배분 법리). 복수 출처 확인 상태. ※ 대법 94누15929는 단일 출처로 인용 배제 확정, 98두3075만 인용. | H35: 05_상속재산의_범위.md L130 | I35: 미확인 | N35: ※ 대법 94누15929는 단일 출처로 인용 배제 확정, 98두3075만 인용 | O35: 5|L0130|1 | P35: 미확인
A36: 35 | B36: 5 | C36: 5.5 사례 5-5 〔함정〕 | D36: 🔴 최우선 | E36: [검증필요: §15② 산입액 산정 방식의 시행령 원문 대조] | F36: §15② · 시행령 §11④ · 법 §15② · §11③ · §15① | G36: §15② 산입액 산정 방식의 시행령 원문 대조. → ✅ 검증 완료: 비금융기관 채무에는 20%/2억 차감이 없다. 시행령 §11④는 "제2항"만 인용하므로 법 §15②(국가·지자체·금융회사등이 아닌 자에 대한 채무 → 령 §11③)는 미입증금액 전액 산입. §15①과 혼동 금지. 출처 동 파일 상속재산 2. → 사례 5-5의 6,000만원 차이 서술은 이 확정으로 뒷받침됨. | H36: 05_상속재산의_범위.md L205 | I36: 확인완료 | N36: verify_*.md 원문대조로 확정 — 남은 작업은 원고 마커 삭제 + 출처 각주 | O36: 5|L0205|1 | P36: 확인완료
A37: 36 | B37: 5 | C37: 5.6 자주 묻는 질문 | D37: 🟢 보완 | E37: [검증필요: 저축성 보험의 보험차익 과세와 사망보험금의 경계] | F37: 시행령 §25① | G37: 저축성 보험 보험차익 과세와 사망보험금의 경계. → ✅ 검증 완료: 사망보험금은 소득세법상 이자소득 과세대상이 아니다(소득세법 시행령 §25①이 "저축성보험의 보험차익" 정의에서 사망·질병·상해로 받는 것을 배제). 출처 동 파일 상속재산 7. 잔여: 사망보험금 지연이자의 소득세 취급은 미확정. | H37: 05_상속재산의_범위.md L215 | I37: 확인완료 | N37: verify_*.md 원문대조로 확정 — 남은 작업은 원고 마커 삭제 + 출처 각주 | O37: 5|L0215|1 | P37: 확인완료
A38: 37 | B38: 6 | C38: 6.2 법령 근거 (법 §13·§28) | D38: 🟡 중요 | E38: [검증필요: §47① 합산배제증여재산의 구체적 열거 범위 — 재산취득 후 가치증가분·전환사채 이익·상장 이익 등의 조문번호 대조. 이 책의 검증 체크리스트에 이미 등재된 항목이다] | F38: §47① | G38: §47① 합산배제증여재산의 구체적 열거 범위 — 재산취득 후 가치증가분·전환사채 이익·상장 이익 등의 조문번호 대조. ※ 16장(유형별 증여)과 연동. | H38: 06_사전증여재산_합산.md L52 | I38: 미확인 | N38: ※ 16장(유형별 증여)과 연동 | O38: 6|L0052|1 | P38: 미확인
A39: 38 | B39: 6 | C39: 6.2 법령 근거 | D39: 🔴 최우선 | E39: [검증필요: 한도 규정의 항 번호와 산식 자구, 수증자가 상속인·수유자인 경우의 상속인별 안분 여부 — law.go.kr 현행본 대조] | F39: 법 §28 · §28② | G39: 증여세액공제 한도(법 §28)의 항 번호와 산식 자구, 수증자가 상속인·수유자인 경우의 상속인별 안분 여부. 사례 6-2·6-3의 계산 전제이자 "환급은 일어나지 않는다"는 결론의 근거. ※ 구 체크리스트의 "사례 9-2 §28② 안분한도" 항목이 여기로 통합됨. | H39: 06_사전증여재산_합산.md L62 | I39: 미확인 | N39: ※ 구 체크리스트의 "사례 9-2 §28② 안분한도" 항목이 여기로 통합됨 | O39: 6|L0062|1 | P39: 미확인
A40: 39 | B40: 6 | C40: 6.5 자주 묻는 질문 | D40: 🟡 중요 | E40: [검증필요: 상속인 지위 판정의 기준 시점 — law.go.kr 제13조 원문 및 국세청 해석 대조] | F40: §13 | G40: 상속인 지위 판정의 기준 시점(증여 시점 vs 상속개시 시점) — law.go.kr §13 원문 및 국세청 해석 대조. 5년/10년을 가르므로 실무 영향 큼. | H40: 06_사전증여재산_합산.md L221 | I40: 미확인 | O40: 6|L0221|1 | P40: 미확인
...

Sheet ② 요약
A1: 원문 대조 진행 현황
A2: 상태 열(① 작업표 I열)을 채우면 아래 수치·진행률이 자동으로 갱신된다.
A4: ■ 전체
A5: 총 등재 건수 | C5: =COUNTA('① 작업표'!$A$2:$A$2000)
A6: 확인완료 | C6: =COUNTIF('① 작업표'!$I$2:$I$2000,"확인완료")
A7: 확인중 | C7: =COUNTIF('① 작업표'!$I$2:$I$2000,"확인중")
A8: 미확인 | C8: =COUNTIF('① 작업표'!$I$2:$I$2000,"미확인")
A9: 수정필요 | C9: =COUNTIF('① 작업표'!$I$2:$I$2000,"수정필요")
A10: 해당없음(표기용) | C10: =COUNTIF('① 작업표'!$I$2:$I$2000,"해당없음")
A11: 전체 진행률 | C11: =IFERROR(COUNTIF('① 작업표'!$I$2:$I$2000,"확인완료")/(COUNTA('① 작업표'!$A$2:$A$2000)-COUNTIF('① 작업표'!$I$2:$I$2000,"해당없음")),"") | J11: 분모는 ⚪ 표기용 10건을 뺀 실제 검증 대상 기준
A12: 🔴 최우선 진행률 | C12: =IFERROR(COUNTIFS('① 작업표'!$D$2:$D$2000,"🔴 최우선",'① 작업표'!$I$2:$I$2000,"확인완료")/COUNTIF('① 작업표'!$D$2:$D$2000,"🔴 최우선"),"") | J12: 🔴은 어떤 경우에도 미해소 상태로 출판하지 말 것 (체크리스트 §0.2)
A14: ■ 우선순위별
A15: 우선순위 | B15: 기준 — 틀렸을 때의 결과 | C15: 등재 | D15: 확인완료 | E15: 확인중 | F15: 미확인 | G15: 수정필요 | H15: 해당없음 | I15: 진행률
A16: 🔴 최우선 | B16: 금액·세율·한도·비율·요건 연수·산식 — 세액이 틀어진다 | C16: =COUNTIF('① 작업표'!$D$2:$D$2000,"🔴 최우선") | D16: =COUNTIFS('① 작업표'!$D$2:$D$2000,"🔴 최우선",'① 작업표'!$I$2:$I$2000,"확인완료") | E16: =COUNTIFS('① 작업표'!$D$2:$D$2000,"🔴 최우선",'① 작업표'!$I$2:$I$2000,"확인중") | F16: =COUNTIFS('① 작업표'!$D$2:$D$2000,"🔴 최우선",'① 작업표'!$I$2:$I$2000,"미확인") | G16: =COUNTIFS('① 작업표'!$D$2:$D$2000,"🔴 최우선",'① 작업표'!$I$2:$I$2000,"수정필요") | H16: =COUNTIFS('① 작업표'!$D$2:$D$2000,"🔴 최우선",'① 작업표'!$I$2:$I$2000,"해당없음") | I16: =IFERROR(D16/(C16-H16),"")
A17: 🟡 중요 | B17: 조문번호·항·호 배치, 법문 축자 표현, 준용 관계 — 인용이 틀린다 | C17: =COUNTIF('① 작업표'!$D$2:$D$2000,"🟡 중요") | D17: =COUNTIFS('① 작업표'!$D$2:$D$2000,"🟡 중요",'① 작업표'!$I$2:$I$2000,"확인완료") | E17: =COUNTIFS('① 작업표'!$D$2:$D$2000,"🟡 중요",'① 작업표'!$I$2:$I$2000,"확인중") | F17: =COUNTIFS('① 작업표'!$D$2:$D$2000,"🟡 중요",'① 작업표'!$I$2:$I$2000,"미확인") | G17: =COUNTIFS('① 작업표'!$D$2:$D$2000,"🟡 중요",'① 작업표'!$I$2:$I$2000,"수정필요") | H17: =COUNTIFS('① 작업표'!$D$2:$D$2000,"🟡 중요",'① 작업표'!$I$2:$I$2000,"해당없음") | I17: =IFERROR(D17/(C17-H17),"")
A18: 🟢 보완 | B18: 예규·판례 사건번호, 서식 명칭, 절차·통계 — 신뢰도가 깎인다 | C18: =COUNTIF('① 작업표'!$D$2:$D$2000,"🟢 보완") | D18: =COUNTIFS('① 작업표'!$D$2:$D$2000,"🟢 보완",'① 작업표'!$I$2:$I$2000,"확인완료") | E18: =COUNTIFS('① 작업표'!$D$2:$D$2000,"🟢 보완",'① 작업표'!$I$2:$I$2000,"확인중") | F18: =COUNTIFS('① 작업표'!$D$2:$D$2000,"🟢 보완",'① 작업표'!$I$2:$I$2000,"미확인") | G18: =COUNTIFS('① 작업표'!$D$2:$D$2000,"🟢 보완",'① 작업표'!$I$2:$I$2000,"수정필요") | H18: =COUNTIFS('① 작업표'!$D$2:$D$2000,"🟢 보완",'① 작업표'!$I$2:$I$2000,"해당없음") | I18: =IFERROR(D18/(C18-H18),"")
A19: ⚪ 표기 | B19: 표기 설명·상호참조 — 원문 조회 대상이 아니며 마커를 지우지 말 것 | C19: =COUNTIF('① 작업표'!$D$2:$D$2000,"⚪ 표기") | D19: =COUNTIFS('① 작업표'!$D$2:$D$2000,"⚪ 표기",'① 작업표'!$I$2:$I$2000,"확인완료") | E19: =COUNTIFS('① 작업표'!$D$2:$D$2000,"⚪ 표기",'① 작업표'!$I$2:$I$2000,"확인중") | F19: =COUNTIFS('① 작업표'!$D$2:$D$2000,"⚪ 표기",'① 작업표'!$I$2:$I$2000,"미확인") | G19: =COUNTIFS('① 작업표'!$D$2:$D$2000,"⚪ 표기",'① 작업표'!$I$2:$I$2000,"수정필요") | H19: =COUNTIFS('① 작업표'!$D$2:$D$2000,"⚪ 표기",'① 작업표'!$I$2:$I$2000,"해당없음") | I19: =IFERROR(D19/(C19-H19),"")
A21: ■ 장별
A22: 장 | B22: 제목(약칭) | C22: 마커 | D22: 🔴 | E22: 🟡 | F22: 🟢 | G22: ⚪ | H22: 확인완료 | I22: 진행률 | J22: 집중 검증 권고
A23: 1 | B23: 상속·증여와 세금 전체 그림 | C23: =COUNTIF('① 작업표'!$B$2:$B$2000,1) | D23: =COUNTIFS('① 작업표'!$B$2:$B$2000,1,'① 작업표'!$D$2:$D$2000,"🔴 최우선") | E23: =COUNTIFS('① 작업표'!$B$2:$B$2000,1,'① 작업표'!$D$2:$D$2000,"🟡 중요") | F23: =COUNTIFS('① 작업표'!$B$2:$B$2000,1,'① 작업표'!$D$2:$D$2000,"🟢 보완") | G23: =COUNTIFS('① 작업표'!$B$2:$B$2000,1,'① 작업표'!$D$2:$D$2000,"⚪ 표기") | H23: =COUNTIFS('① 작업표'!$B$2:$B$2000,1,'① 작업표'!$I$2:$I$2000,"확인완료") | I23: =IFERROR(H23/(C23-G23),"")
A24: 2 | B24: 상증세법의 구조와 법령체계 | C24: =COUNTIF('① 작업표'!$B$2:$B$2000,2) | D24: =COUNTIFS('① 작업표'!$B$2:$B$2000,2,'① 작업표'!$D$2:$D$2000,"🔴 최우선") | E24: =COUNTIFS('① 작업표'!$B$2:$B$2000,2,'① 작업표'!$D$2:$D$2000,"🟡 중요") | F24: =COUNTIFS('① 작업표'!$B$2:$B$2000,2,'① 작업표'!$D$2:$D$2000,"🟢 보완") | G24: =COUNTIFS('① 작업표'!$B$2:$B$2000,2,'① 작업표'!$D$2:$D$2000,"⚪ 표기") | H24: =COUNTIFS('① 작업표'!$B$2:$B$2000,2,'① 작업표'!$I$2:$I$2000,"확인완료") | I24: =IFERROR(H24/(C24-G24),"")
A25: 3 | B25: 상속의 민법 기초 | C25: =COUNTIF('① 작업표'!$B$2:$B$2000,3) | D25: =COUNTIFS('① 작업표'!$B$2:$B$2000,3,'① 작업표'!$D$2:$D$2000,"🔴 최우선") | E25: =COUNTIFS('① 작업표'!$B$2:$B$2000,3,'① 작업표'!$D$2:$D$2000,"🟡 중요") | F25: =COUNTIFS('① 작업표'!$B$2:$B$2000,3,'① 작업표'!$D$2:$D$2000,"🟢 보완") | G25: =COUNTIFS('① 작업표'!$B$2:$B$2000,3,'① 작업표'!$D$2:$D$2000,"⚪ 표기") | H25: =COUNTIFS('① 작업표'!$B$2:$B$2000,3,'① 작업표'!$I$2:$I$2000,"확인완료") | I25: =IFERROR(H25/(C25-G25),"") | J25: 제3장 (상속의 민법 기초) — 11건, 최다. 🟡이 7건으로 몰려 있다. 세법이 아니라 민법이라 저자의 조사 밀도가 가장 낮았던 구간이고, 2026.2. 민법 개정(유류분·상속권 상실)이 겹쳐 개정 직후 조문을 다룬다. 유류분 관련 3건(특별수익·기여분·산입 증여 범위)은 서로 물려 있으므로 한 사람이 묶어서 보는 편이 빠르다. → 민법 전공 변호사 배정 권장.
A26: 4 | B26: 과세대상과 납세의무자 | C26: =COUNTIF('① 작업표'!$B$2:$B$2000,4) | D26: =COUNTIFS('① 작업표'!$B$2:$B$2000,4,'① 작업표'!$D$2:$D$2000,"🔴 최우선") | E26: =COUNTIFS('① 작업표'!$B$2:$B$2000,4,'① 작업표'!$D$2:$D$2000,"🟡 중요") | F26: =COUNTIFS('① 작업표'!$B$2:$B$2000,4,'① 작업표'!$D$2:$D$2000,"🟢 보완") | G26: =COUNTIFS('① 작업표'!$B$2:$B$2000,4,'① 작업표'!$D$2:$D$2000,"⚪ 표기") | H26: =COUNTIFS('① 작업표'!$B$2:$B$2000,4,'① 작업표'!$I$2:$I$2000,"확인완료") | I26: =IFERROR(H26/(C26-G26),"") | J26: 제4장 (7건, 🟡 5건). §3의2 2026.1.1. 시행 개정이 걸려 있어 개정 전후 문언 대비가 필요하다. 부칙 원문까지 봐야 한다.
A27: 5 | B27: 상속재산의 범위 | C27: =COUNTIF('① 작업표'!$B$2:$B$2000,5) | D27: =COUNTIFS('① 작업표'!$B$2:$B$2000,5,'① 작업표'!$D$2:$D$2000,"🔴 최우선") | E27: =COUNTIFS('① 작업표'!$B$2:$B$2000,5,'① 작업표'!$D$2:$D$2000,"🟡 중요") | F27: =COUNTIFS('① 작업표'!$B$2:$B$2000,5,'① 작업표'!$D$2:$D$2000,"🟢 보완") | G27: =COUNTIFS('① 작업표'!$B$2:$B$2000,5,'① 작업표'!$D$2:$D$2000,"⚪ 표기") | H27: =COUNTIFS('① 작업표'!$B$2:$B$2000,5,'① 작업표'!$I$2:$I$2000,"확인완료") | I27: =IFERROR(H27/(C27-G27),"")
A28: 6 | B28: 사전증여재산 합산 | C28: =COUNTIF('① 작업표'!$B$2:$B$2000,6) | D28: =COUNTIFS('① 작업표'!$B$2:$B$2000,6,'① 작업표'!$D$2:$D$2000,"🔴 최우선") | E28: =COUNTIFS('① 작업표'!$B$2:$B$2000,6,'① 작업표'!$D$2:$D$2000,"🟡 중요") | F28: =COUNTIFS('① 작업표'!$B$2:$B$2000,6,'① 작업표'!$D$2:$D$2000,"🟢 보완") | G28: =COUNTIFS('① 작업표'!$B$2:$B$2000,6,'① 작업표'!$D$2:$D$2000,"⚪ 표기") | H28: =COUNTIFS('① 작업표'!$B$2:$B$2000,6,'① 작업표'!$I$2:$I$2000,"확인완료") | I28: =IFERROR(H28/(C28-G28),"")
A29: 7 | B29: 상속세 과세가액 | C29: =COUNTIF('① 작업표'!$B$2:$B$2000,7) | D29: =COUNTIFS('① 작업표'!$B$2:$B$2000,7,'① 작업표'!$D$2:$D$2000,"🔴 최우선") | E29: =COUNTIFS('① 작업표'!$B$2:$B$2000,7,'① 작업표'!$D$2:$D$2000,"🟡 중요") | F29: =COUNTIFS('① 작업표'!$B$2:$B$2000,7,'① 작업표'!$D$2:$D$2000,"🟢 보완") | G29: =COUNTIFS('① 작업표'!$B$2:$B$2000,7,'① 작업표'!$D$2:$D$2000,"⚪ 표기") | H29: =COUNTIFS('① 작업표'!$B$2:$B$2000,7,'① 작업표'!$I$2:$I$2000,"확인완료") | I29: =IFERROR(H29/(C29-G29),"")
A30: 8 | B30: 상속공제 I (기초·일괄·인적) | C30: =COUNTIF('① 작업표'!$B$2:$B$2000,8) | D30: =COUNTIFS('① 작업표'!$B$2:$B$2000,8,'① 작업표'!$D$2:$D$2000,"🔴 최우선") | E30: =COUNTIFS('① 작업표'!$B$2:$B$2000,8,'① 작업표'!$D$2:$D$2000,"🟡 중요") | F30: =COUNTIFS('① 작업표'!$B$2:$B$2000,8,'① 작업표'!$D$2:$D$2000,"🟢 보완") | G30: =COUNTIFS('① 작업표'!$B$2:$B$2000,8,'① 작업표'!$D$2:$D$2000,"⚪ 표기") | H30: =COUNTIFS('① 작업표'!$B$2:$B$2000,8,'① 작업표'!$I$2:$I$2000,"확인완료") | I30: =IFERROR(H30/(C30-G30),"")
A31: 9 | B31: 상속공제 II (배우자) | C31: =COUNTIF('① 작업표'!$B$2:$B$2000,9) | D31: =COUNTIFS('① 작업표'!$B$2:$B$2000,9,'① 작업표'!$D$2:$D$2000,"🔴 최우선") | E31: =COUNTIFS('① 작업표'!$B$2:$B$2000,9,'① 작업표'!$D$2:$D$2000,"🟡 중요") | F31: =COUNTIFS('① 작업표'!$B$2:$B$2000,9,'① 작업표'!$D$2:$D$2000,"🟢 보완") | G31: =COUNTIFS('① 작업표'!$B$2:$B$2000,9,'① 작업표'!$D$2:$D$2000,"⚪ 표기") | H31: =COUNTIFS('① 작업표'!$B$2:$B$2000,9,'① 작업표'!$I$2:$I$2000,"확인완료") | I31: =IFERROR(H31/(C31-G31),"")
A32: 10 | B32: 상속공제 III (금융·동거주택) | C32: =COUNTIF('① 작업표'!$B$2:$B$2000,10) | D32: =COUNTIFS('① 작업표'!$B$2:$B$2000,10,'① 작업표'!$D$2:$D$2000,"🔴 최우선") | E32: =COUNTIFS('① 작업표'!$B$2:$B$2000,10,'① 작업표'!$D$2:$D$2000,"🟡 중요") | F32: =COUNTIFS('① 작업표'!$B$2:$B$2000,10,'① 작업표'!$D$2:$D$2000,"🟢 보완") | G32: =COUNTIFS('① 작업표'!$B$2:$B$2000,10,'① 작업표'!$D$2:$D$2000,"⚪ 표기") | H32: =COUNTIFS('① 작업표'!$B$2:$B$2000,10,'① 작업표'!$I$2:$I$2000,"확인완료") | I32: =IFERROR(H32/(C32-G32),"")
A33: 11 | B33: 가업상속공제·영농상속공제 | C33: =COUNTIF('① 작업표'!$B$2:$B$2000,11) | D33: =COUNTIFS('① 작업표'!$B$2:$B$2000,11,'① 작업표'!$D$2:$D$2000,"🔴 최우선") | E33: =COUNTIFS('① 작업표'!$B$2:$B$2000,11,'① 작업표'!$D$2:$D$2000,"🟡 중요") | F33: =COUNTIFS('① 작업표'!$B$2:$B$2000,11,'① 작업표'!$D$2:$D$2000,"🟢 보완") | G33: =COUNTIFS('① 작업표'!$B$2:$B$2000,11,'① 작업표'!$D$2:$D$2000,"⚪ 표기") | H33: =COUNTIFS('① 작업표'!$B$2:$B$2000,11,'① 작업표'!$I$2:$I$2000,"확인완료") | I33: =IFERROR(H33/(C33-G33),"")
A34: 12 | B34: 세율과 세액 계산 | C34: =COUNTIF('① 작업표'!$B$2:$B$2000,12) | D34: =COUNTIFS('① 작업표'!$B$2:$B$2000,12,'① 작업표'!$D$2:$D$2000,"🔴 최우선") | E34: =COUNTIFS('① 작업표'!$B$2:$B$2000,12,'① 작업표'!$D$2:$D$2000,"🟡 중요") | F34: =COUNTIFS('① 작업표'!$B$2:$B$2000,12,'① 작업표'!$D$2:$D$2000,"🟢 보완") | G34: =COUNTIFS('① 작업표'!$B$2:$B$2000,12,'① 작업표'!$D$2:$D$2000,"⚪ 표기") | H34: =COUNTIFS('① 작업표'!$B$2:$B$2000,12,'① 작업표'!$I$2:$I$2000,"확인완료") | I34: =IFERROR(H34/(C34-G34),"")
A35: 13 | B35: 비거주자와 국제상속 | C35: =COUNTIF('① 작업표'!$B$2:$B$2000,13) | D35: =COUNTIFS('① 작업표'!$B$2:$B$2000,13,'① 작업표'!$D$2:$D$2000,"🔴 최우선") | E35: =COUNTIFS('① 작업표'!$B$2:$B$2000,13,'① 작업표'!$D$2:$D$2000,"🟡 중요") | F35: =COUNTIFS('① 작업표'!$B$2:$B$2000,13,'① 작업표'!$D$2:$D$2000,"🟢 보완") | G35: =COUNTIFS('① 작업표'!$B$2:$B$2000,13,'① 작업표'!$D$2:$D$2000,"⚪ 표기") | H35: =COUNTIFS('① 작업표'!$B$2:$B$2000,13,'① 작업표'!$I$2:$I$2000,"확인완료") | I35: =IFERROR(H35/(C35-G35),"") | J35: 제13장 (비거주자와 국제상속) — 10건, 🔴 4건으로 최다. 거주자 판정(183일 계산)·국외전출세 세율·해외금융계좌 과태료율·§53 거주자 요건이 전부 🔴다. 게다가 소득세법·국제조세조정법·조세조약이라는 이 책 바깥의 법령을 인용하는 장이라 상증세법만 아는 검토자로는 닫히지 않는다. → 국제조세 담당자 배정 권장.
A36: 14 | B36: 증여세 과세대상과 납세의무자 | C36: =COUNTIF('① 작업표'!$B$2:$B$2000,14) | D36: =COUNTIFS('① 작업표'!$B$2:$B$2000,14,'① 작업표'!$D$2:$D$2000,"🔴 최우선") | E36: =COUNTIFS('① 작업표'!$B$2:$B$2000,14,'① 작업표'!$D$2:$D$2000,"🟡 중요") | F36: =COUNTIFS('① 작업표'!$B$2:$B$2000,14,'① 작업표'!$D$2:$D$2000,"🟢 보완") | G36: =COUNTIFS('① 작업표'!$B$2:$B$2000,14,'① 작업표'!$D$2:$D$2000,"⚪ 표기") | H36: =COUNTIFS('① 작업표'!$B$2:$B$2000,14,'① 작업표'!$I$2:$I$2000,"확인완료") | I36: =IFERROR(H36/(C36-G36),"")
A37: 15 | B37: 증여재산공제 | C37: =COUNTIF('① 작업표'!$B$2:$B$2000,15) | D37: =COUNTIFS('① 작업표'!$B$2:$B$2000,15,'① 작업표'!$D$2:$D$2000,"🔴 최우선") | E37: =COUNTIFS('① 작업표'!$B$2:$B$2000,15,'① 작업표'!$D$2:$D$2000,"🟡 중요") | F37: =COUNTIFS('① 작업표'!$B$2:$B$2000,15,'① 작업표'!$D$2:$D$2000,"🟢 보완") | G37: =COUNTIFS('① 작업표'!$B$2:$B$2000,15,'① 작업표'!$D$2:$D$2000,"⚪ 표기") | H37: =COUNTIFS('① 작업표'!$B$2:$B$2000,15,'① 작업표'!$I$2:$I$2000,"확인완료") | I37: =IFERROR(H37/(C37-G37),"")
A38: 16 | B38: 유형별 증여 | C38: =COUNTIF('① 작업표'!$B$2:$B$2000,16) | D38: =COUNTIFS('① 작업표'!$B$2:$B$2000,16,'① 작업표'!$D$2:$D$2000,"🔴 최우선") | E38: =COUNTIFS('① 작업표'!$B$2:$B$2000,16,'① 작업표'!$D$2:$D$2000,"🟡 중요") | F38: =COUNTIFS('① 작업표'!$B$2:$B$2000,16,'① 작업표'!$D$2:$D$2000,"🟢 보완") | G38: =COUNTIFS('① 작업표'!$B$2:$B$2000,16,'① 작업표'!$D$2:$D$2000,"⚪ 표기") | H38: =COUNTIFS('① 작업표'!$B$2:$B$2000,16,'① 작업표'!$I$2:$I$2000,"확인완료") | I38: =IFERROR(H38/(C38-G38),"")
A39: 17 | B39: 부담부증여 | C39: =COUNTIF('① 작업표'!$B$2:$B$2000,17) | D39: =COUNTIFS('① 작업표'!$B$2:$B$2000,17,'① 작업표'!$D$2:$D$2000,"🔴 최우선") | E39: =COUNTIFS('① 작업표'!$B$2:$B$2000,17,'① 작업표'!$D$2:$D$2000,"🟡 중요") | F39: =COUNTIFS('① 작업표'!$B$2:$B$2000,17,'① 작업표'!$D$2:$D$2000,"🟢 보완") | G39: =COUNTIFS('① 작업표'!$B$2:$B$2000,17,'① 작업표'!$D$2:$D$2000,"⚪ 표기") | H39: =COUNTIFS('① 작업표'!$B$2:$B$2000,17,'① 작업표'!$I$2:$I$2000,"확인완료") | I39: =IFERROR(H39/(C39-G39),"")
A40: 18 | B40: 증여추정과 증여의제 | C40: =COUNTIF('① 작업표'!$B$2:$B$2000,18) | D40: =COUNTIFS('① 작업표'!$B$2:$B$2000,18,'① 작업표'!$D$2:$D$2000,"🔴 최우선") | E40: =COUNTIFS('① 작업표'!$B$2:$B$2000,18,'① 작업표'!$D$2:$D$2000,"🟡 중요") | F40: =COUNTIFS('① 작업표'!$B$2:$B$2000,18,'① 작업표'!$D$2:$D$2000,"🟢 보완") | G40: =COUNTIFS('① 작업표'!$B$2:$B$2000,18,'① 작업표'!$D$2:$D$2000,"⚪ 표기") | H40: =COUNTIFS('① 작업표'!$B$2:$B$2000,18,'① 작업표'!$I$2:$I$2000,"확인완료") | I40: =IFERROR(H40/(C40-G40),"")
A41: 19 | B41: 창업자금·가업승계 과세특례 | C41: =COUNTIF('① 작업표'!$B$2:$B$2000,19) | D41: =COUNTIFS('① 작업표'!$B$2:$B$2000,19,'① 작업표'!$D$2:$D$2000,"🔴 최우선") | E41: =COUNTIFS('① 작업표'!$B$2:$B$2000,19,'① 작업표'!$D$2:$D$2000,"🟡 중요") | F41: =COUNTIFS('① 작업표'!$B$2:$B$2000,19,'① 작업표'!$D$2:$D$2000,"🟢 보완") | G41: =COUNTIFS('① 작업표'!$B$2:$B$2000,19,'① 작업표'!$D$2:$D$2000,"⚪ 표기") | H41: =COUNTIFS('① 작업표'!$B$2:$B$2000,19,'① 작업표'!$I$2:$I$2000,"확인완료") | I41: =IFERROR(H41/(C41-G41),"")
A42: 20 | B42: 신탁과 상속·증여 | C42: =COUNTIF('① 작업표'!$B$2:$B$2000,20) | D42: =COUNTIFS('① 작업표'!$B$2:$B$2000,20,'① 작업표'!$D$2:$D$2000,"🔴 최우선") | E42: =COUNTIFS('① 작업표'!$B$2:$B$2000,20,'① 작업표'!$D$2:$D$2000,"🟡 중요") | F42: =COUNTIFS('① 작업표'!$B$2:$B$2000,20,'① 작업표'!$D$2:$D$2000,"🟢 보완") | G42: =COUNTIFS('① 작업표'!$B$2:$B$2000,20,'① 작업표'!$D$2:$D$2000,"⚪ 표기") | H42: =COUNTIFS('① 작업표'!$B$2:$B$2000,20,'① 작업표'!$I$2:$I$2000,"확인완료") | I42: =IFERROR(H42/(C42-G42),"")
A43: 21 | B43: 평가 원칙 | C43: =COUNTIF('① 작업표'!$B$2:$B$2000,21) | D43: =COUNTIFS('① 작업표'!$B$2:$B$2000,21,'① 작업표'!$D$2:$D$2000,"🔴 최우선") | E43: =COUNTIFS('① 작업표'!$B$2:$B$2000,21,'① 작업표'!$D$2:$D$2000,"🟡 중요") | F43: =COUNTIFS('① 작업표'!$B$2:$B$2000,21,'① 작업표'!$D$2:$D$2000,"🟢 보완") | G43: =COUNTIFS('① 작업표'!$B$2:$B$2000,21,'① 작업표'!$D$2:$D$2000,"⚪ 표기") | H43: =COUNTIFS('① 작업표'!$B$2:$B$2000,21,'① 작업표'!$I$2:$I$2000,"확인완료") | I43: =IFERROR(H43/(C43-G43),"")
...

Sheet ③ 확인 방법
A1: 절 | B1: 구분 | C1: 내용 / URL / 값
B2: 메모 | C2: 아래 경로는 05_review/verify_*.md 5개 파일에서 실제로 원문 취득에 성공한 경로다. 추정 경로가 아니라 실증된 경로이므로 그대로 쓰면 된다.
A3: 1.1 law.go.kr DRF 오픈API — 조문 축자 원문 (🔴·🟡 항목의 기본 도구)
A4: 1.1 | B4: URL 패턴 | C4: https://www.law.go.kr/DRF/lawService.do?OC=test&target=law&type=XML&LM={법령명}&JO={조문번호}
A5: 1.1 | B5: 설명 | C5: LM = 법령명 (예: 상속세 및 증여세법, 상속세 및 증여세법 시행령)
A6: 1.1 | B6: 설명 | C6: JO = 조문번호 6자리 (예: 제19조 → 001900, 제18조의2 → 001802)
A7: 1.1 | B7: 설명 | C7: type=XML 대신 type=JSON도 가능. XML 본문을 직접 파싱하면 항·호 번호까지 축자로 잡힌다.
A8: 1.1 | B8: 설명 | C8: 버전을 고정하려면 MST를 쓴다 (LM 대신 MST={번호}). 2026-08-13 확인된 MST:
A9: 1.1 | B9: 표 머리 | C9: 법령 | D9: 버전 | E9: MST
A10: 1.1 | B10: 표 | C10: 상속세 및 증여세법 | D10: 법률 제21065호 (시행 2026.1.2.) | E10: 276123
A11: 1.1 | B11: 표 | C11: 상속세 및 증여세법 시행령 | D11: 대통령령 제36131호 (시행 2026.2.27.) | E11: 283637
A12: 1.1 | B12: 표 | C12: 상속세 및 증여세법 시행규칙 | D12: 재정경제부령 (시행 2026.3.20.) | E12: 284609
A13: 1.1 | B13: 메모 | C13: MST는 법령의 특정 버전을 가리킨다. 개정되면 새 MST가 생기므로, 위 번호는 "2026년의 이 버전"을 다시 불러오는 좌표이기도 하다. 감정·심판청구·의견서처럼 근거를 남겨야 하는 실무에서는 화면 캡처보다 버전이 특정된 원문 텍스트가 훨씬 강하다.
A14: 1.2 ⚠ 함정 — 화면 페이지는 본문을 주지 않는다
A15: 1.2 | B15: 주의 | C15: law.go.kr의 일반 조문 화면은 프레임(frame) 구조여서, URL을 그대로 긁으면 본문이 아니라 껍데기만 잡힌다. 이 함정 때문에 2차 출처(블로그·세무 포털)로 새는 사고가 반복된다. 반드시 §1.1의 DRF API 또는 아래 인쇄뷰를 쓸 것.
A16: 1.2 | B16: 설명 | C16: 인쇄뷰 경로(실증됨):
A17: 1.2 | B17: URL 패턴 | C17: https://www.law.go.kr/lsLawLinkInfo.do?lsJoLnkSeq={SEQ}&lsId={ID}&chrClsCd=010202&print=print
A18: 1.2 | B18: 설명 | C18: 확인된 값 — 법 제4장(제60~66조): lsJoLnkSeq=900368850&lsId=001561 / 시행령 제63조: lsJoLnkSeq=1000087016
A19: 1.2 | B19: 설명 | C19: 그 밖에 본문 취득에 성공한 경로: lsLinkCommonInfo.do(법 제60~66조), lumLsLinkPop.do(시행령 제50조·제52조의2)
A20: 1.2 | B20: 주의 | C20: 연혁법령(구법) API는 500 오류가 잦다. 구법 원문(가업상속 기간별 추징률 표 등)은 이 경로로 취득 실패한 이력이 있으므로, 국회 의안정보시스템·관보 아카이브를 대안으로 준비할 것.
A21: 1.2 | B21: 설명 | C21: 한계 — 이미지 수식. 법 제19조 제1항 제1호의 배우자상속공제 한도식은 law.go.kr 게재본이 이미지여서 API로도 축자 텍스트가 나오지 않는다. 이런 항목은 종이 법전 또는 관보로 대조해야 한다.
A22: 1.3 판례 — 대법원 종합법률정보
A23: 1.3 | B23: 설명 | C23: https://lx.scourt.go.kr 판례 검색. 상세 URL 패턴(실증): lx.scourt.go.kr/search/detail/precedent/0/2026000036467 (대법원 2026.4.2. 선고 2025두35499)
A24: 1.3 | B24: 설명 | C24: 언론 보도로만 확인된 사건번호는 인용하지 않는다. 원고의 21장 판례 2건이 여기에 해당한다(언론 3곳 교차확인 상태, 공식 DB 미대조).
A25: 1.3 | B25: 설명 | C25: 하급심(행정법원·고등법원) 사건은 공개 범위가 좁다. 확정 여부·상급심 진행을 확인하지 못하면 "~라고 본 하급심 판결이 있다" 수준으로 낮춰 쓴다.
A26: 1.4 예규·집행기준·심판례
A27: 1.4 | B27: 설명 | C27: 국세법령정보시스템 https://txsi.hometax.go.kr — 예규(사전-2023-법규재산-0247 형식)·집행기준·질의회신 원문. 원고가 인용한 예규는 대부분 2차 출처 경유이므로 문서번호가 실재하는지부터 확인할 것.
A28: 1.4 | B28: 설명 | C28: 조세심판원 https://www.tt.go.kr — 심판례(조심 2024중5770 형식).
A29: 1.4 | B29: 설명 | C29: 예규·집행기준은 법이 아니라 국세청 해석이다. 인용할 때 반드시 층위를 문장에 드러낸다("국세청 해석(사전-2025-법규재산-0190)에 따르면").
A30: 1.5 훈령·통계·기타
A31: 1.5 | B31: 설명 | C31: 국세청 훈령 — 「상속세 및 증여세 사무처리규정」(제2760호, 시행 2026.8.3.), 「평가심의위원회 운영 규정」(제2545호, 2022.12.22.). 국세청 누리집 훈령·예규 게시판. 훈령은 개정이 잦다 — 증여추정 배제기준(§42)·부동산 감정평가 선정기준(§72)은 매 개정판 재확인 대상.
A32: 1.5 | B32: 설명 | C32: 국세통계포털(TASIS) https://tasis.nts.go.kr — 과세인원·결정세액 등 통계 원자료. 언론 인용 수치를 그대로 쓰지 말 것.
A33: 1.5 | B33: 설명 | C33: 국가법령정보센터 부칙·신구조문대비표 — 개정 전후 문언 대비(4장 §3의2·23장 국기법 §47의4에 필수).
A34: 1.6 확인할 때의 기록 규칙
A35: 1.6 | B35: 기록 규칙 | C35: [ ] 확인한 항목은 조회일자·법령 버전(법률호수/MST)·조회 URL을 각주 또는 원문대조_작업표.xlsx에 남긴다.
A36: 1.6 | B36: 기록 규칙 | C36: [ ] 확인 결과 원고가 틀렸으면 수정하고, 확정하지 못했으면 마커를 지우지 말 것. 확정하지 못한 것을 확정한 것처럼 쓰는 것이 이 책이 가장 피하려는 실패다.
A37: 1.6 | B37: 기록 규칙 | C37: [ ] 확정된 항목은 원고의 [검증필요] 마커를 삭제하고 출처 각주로 교체한다.

Sheet ④ 확인 완료 이력
A1: 구분 | B1: 분류 | C1: 확정 사항 — 재검증 대상 아님 | D1: 출처 | E1: 비고
A2: 여기 적힌 것은 원문 대조가 끝난 사실이다. 원고가 이와 다르게 쓰고 있다면 원고가 틀린 것이다. 재검토 시 중복 작업을 막는 용도.
A3: ■ 근거 파일 — 05_review/verify_*.md (1차 출처 취득 성공분)
A4: 근거 파일 | B4: verify_61조63조_원문대조.md | C4: 조문 원문대조 검증 결과 — 법 제61조·제63조 (2026-08-13, 22장 검수용) | D4: law.go.kr lsLinkCommonInfo.do (법 제60~66조 원문) · lumLsLinkPop.do (시행령 제50조·제52조의2) | E4: 상속세 및 증여세법 [시행 2026. 1. 2.] [법률 제21065호] / 시행령 [시행 2026. 2. 27.] [대통령령 제36131호]
A5: 근거 파일 | B5: verify_66조_할증평가_원문대조.md | C5: 조문 원문대조 검증 결과 — 법 제66조(저당권 특례)·제63조 제3항(최대주주 할증) (2026-08-13, 21·22장 검수용) | D5: law.go.kr lsLawLinkInfo.do?lsJoLnkSeq={SEQ}&lsId={ID}&chrClsCd=010202&print=print — 법 제4장(제60~66조): lsJoLnkSeq=900368850&lsId=001561 / 시행령 제63조: lsJoLnkSeq=1000087016 | E5: 법률 제21065호(시행 2026.1.2.) / 시행령 제36131호(시행 2026.2.27.)
A6: 근거 파일 | B6: verify_가업상속_추징률_이자상당액.md | C6: 원문대조 검증 결과 — 가업상속공제 추징률·이자상당액 (2026-08-13, 11·19장 검수용) | D6: law.go.kr DRF OPEN API로 조문 XML 원문 직접 취득 (인쇄뷰 + API 2회 독립 취득 일치).
A7: 근거 파일 | B7: verify_상속재산_상속공제_원문대조.md | C7: 원문대조 검증 결과 — 상속재산(§8~§15)·상속공제(§22~§24) (2026-08-13) | D7: law.go.kr DRF OPEN API(lawService.do)로 XML 원문 직접 파싱 — 축자 원문 수준. 프레임 페이지 우회 성공 경로.
A8: 근거 파일 | B8: verify_평가심의위_감정평가사업_원문대조.md | C8: 원문대조 검증 결과 — 평가심의위원회·부동산 감정평가 사업 (2026-08-13, 21·22장 검수용) | D8: 05_review/verify_평가심의위_감정평가사업_원문대조.md (파일 본문에 경로 기재)
A10: ■ verify 확정 사항 — 원고 반영 확인 대상 (체크리스트 §3)
A11: §3 확정 | B11: 3.1 상속재산 (5장) | C11: 시행령 §11⑤ 재산 3분류의 호 번호 함정 — 1호 현금·예금·유가증권 / 2호 부동산 및 부동산에 관한 권리 / 3호 삭제(1998.12.31) / 4호 = 기타 재산 / 5호 삭제. "기타재산 = 제3호"는 오류. 근거 항은 §11①이 아니라 §11⑤. | D11: law.go.kr 원문 (verify_*.md)
A12: §3 확정 | B12: 3.1 상속재산 (5장) | C12: 법 §9③ 수익자연속신탁(2020.12.22 신설) 서술 유무 — 20장과 연동. | D12: law.go.kr 원문 (verify_*.md)
A13: §3 확정 | B13: 3.1 상속재산 (5장) | C13: 법 §10 제2·3호에 「공무원 재해보상법」·「군인 재해보상법」 추가(2018.3.20) 반영. | D13: law.go.kr 원문 (verify_*.md)
A14: §3 확정 | B14: 3.1 상속재산 (5장) | C14: 소명 판정은 적극적 인정 목록이 아니라 시행령 §11② 5가지 부정 요건으로 이루어진다. "병원비는 인정" 식 카탈로그를 썼다면 "실무상 통용되는 예시"로 격하 표기. | D14: law.go.kr 원문 (verify_*.md)
A15: §3 확정 | B15: 3.1 상속재산 (5장) | C15: 금융조회 근거 3단: 법 §83(국세청장·지방국세청장 한정) → 금융실명법 §4①2호·§4⑥5호 → 사무처리규정 §36. | D15: law.go.kr 원문 (verify_*.md)
A16: §3 확정 | B16: 3.2 상속공제 (8·9·10장) | C16: §24 종합한도 표현 4건 정정 — ① "상속인이 아닌 자" → "선순위인 상속인이 아닌 자" ② "상속인의 상속포기로" → "선순위인 상속인의 상속 포기로" ③ "사전증여재산 과세표준" → "증여재산가액(§53·§53의2·§54 공제액 차감 후)"(감정평가수수료 §55①은 차감하지 않으므로 증여세 과세표준과 다르다) ④ 인용 조문은 "제18조, 제18조의2, 제18조의3, 제19조부터 제23조까지 및 제23조의2" — "제18조부터 제23조까지"는 구법. | D16: law.go.kr 원문 (verify_*.md) | E16: 🔴
A17: §3 확정 | B17: 3.2 상속공제 (8·9·10장) | C17: 동거주택상속공제(§23의2) 현행 100%·6억 (40%·5억, 80%·5억은 구법). 동거 기간 특례 3단 구조: 법 §23의2② → 시행령 §20의2② → 시행규칙 §9의2. | D17: law.go.kr 원문 (verify_*.md) | E17: 🔴
A18: §3 확정 | B18: 3.2 상속공제 (8·9·10장) | C18: 금융재산상속공제(§22) — 2천만 초과 시 max(20%, 2천만), 2천만 이하 전액, 2억 한도, 거주자 한정. 범위는 시행령 §19①. | D18: law.go.kr 원문 (verify_*.md) | E18: 🔴
A19: §3 확정 | B19: 3.2 상속공제 (8·9·10장) | C19: 재해손실공제(§23) '재난' 정의는 시행령 §20①. | D19: law.go.kr 원문 (verify_*.md) | E19: 🟡
A20: §3 확정 | B20: 3.3 가업상속·가업승계 (11·19장) | C20: 기간별 추징률 표는 현행법에 없다. 일률 100% (시행령 §15⑮ "100분의 100", 영농은 §16⑦ 동일). 위반유형별 차이는 기간이 아니라 곱셈 인자 — 1호(자산 40%↑ 처분)만 × 자산처분비율, 2·3·4호는 100%. 실무 문헌이 지금도 "기간별 추징율"이라는 용어를 쓰지만 현행 값은 100% 하나다. | D20: law.go.kr 원문 (verify_*.md) | E20: 🔴
A21: §3 확정 | B21: 3.3 가업상속·가업승계 (11·19장) | C21: 이자상당액 이자율은 두 제도가 2.6배 다르다 — 상증법 가업·영농상속공제 연 3.1%(1일 10만분의 8.49; 상증령 §15⑯3호 → 국기령 §43의3② 본문 → 국기칙 §19의3) vs 조특법 가업승계 증여특례 1일 10만분의 22(연 8.03%; 조특령 §27의6⑤3호 → §11의2⑩2호). 같은 표에 넣을 때 반드시 분리 표기. | D21: law.go.kr 원문 (verify_*.md) | E21: 🔴
A22: §3 확정 | B22: 3.3 가업상속·가업승계 (11·19장) | C22: 상증법이 인용하는 것은 국세환급가산금 이자율이지 납부지연가산세가 아니며, "제2항 본문"만 인용하므로 1.5배 단서 미적용. 조문이 "상속세의 부과 당시의 이자율"이라 못박으므로 부과 시점 단일 요율을 전 기간에 적용(기간을 잘라 나누지 않는다). | D22: law.go.kr 원문 (verify_*.md) | E22: 🟡
A23: §3 확정 | B23: 3.4 평가 (21·22장) | C23: 최대주주 할증은 일률 20%. "50% 초과 시 30%", "중소기업 10~15%"는 전부 폐지된 구법 — 게재 금지(2020.1.1.부터 단일 20%). 할증 제외: 중소기업·중견기업·3년 이상 계속 결손 법인. 중소기업 정의는 중소기업기본법 §2(조특법 아님). | D23: law.go.kr 원문 (verify_*.md) | E23: 🔴
A24: §3 확정 | B24: 3.4 평가 (21·22장) | C24: 제61조 제1항 제2호(건물) 현행 문언은 "~등을 고려하여"(참작하여 아님). | D24: law.go.kr 원문 (verify_*.md) | E24: 🟡
A25: §3 확정 | B25: 3.4 평가 (21·22장) | C25: 제63조 제1항 제1호 가목 — '유가증권시장·코스닥시장'은 법이 아니라 시행령 §52조의2 제1항에 명시. "거래소 최종 시세가액"("한국거래소"는 구법), "(거래실적 유무를 따지지 아니한다)"("불문한다" 아님), 매매 없는 날은 전일 기준 단서. | D25: law.go.kr 원문 (verify_*.md) | E25: 🟡
A26: §3 확정 | B26: 3.4 평가 (21·22장) | C26: 코스닥 상장주식은 현행법상 가목으로 평가. 다목은 삭제 <2016.12.20.> — 현행 조문으로 인용 금지. 기업공개 준비 중 주식은 §63②. | D26: law.go.kr 원문 (verify_*.md) | E26: 🟡
A27: §3 확정 | B27: 3.4 평가 (21·22장) | C27: 2개월 기간 계산 특례 = 시행령 §52조의2 제2항(제53조 아님). | D27: law.go.kr 원문 (verify_*.md) | E27: 🟡
... A32: §3 확정 | B32: 3.4 평가 (21·22장) | C32: 예산은 2026년 감액(2025년 96억 → 2026년 67억, 약 30%↓) — "증액" 서술 금지. | D32: law.go.kr 원문 (verify_*.md) | E32: 🟢
A34: ■ 확인 완료 — 그대로 사용 가능한 사실 (체크리스트 §7)
A35: §7 확정 | B35: 7.1 세율·세액 | C35: 세율표 §26: 10/20/30/40/50% + 누진공제 0/1천만/6천만/1.6억/4.6억 (국세청+법제처 법문식 산술 일치 검산) | D35: law.go.kr 원문 (verify_*.md)
A36: §7 확정 | B36: 7.1 세율·세액 | C36: 과세최저한 §25②: 과세표준 50만원 미만 부과 제외 | D36: law.go.kr 원문 (verify_*.md)
A37: §7 확정 | B37: 7.1 세율·세액 | C37: 세대생략 할증 §27: 30%, 미성년자 + 20억 초과 시 40%, 대습상속 제외 | D37: law.go.kr 원문 (verify_*.md)
A38: §7 확정 | B38: 7.1 세율·세액 | C38: 신고세액공제 §69: 3% (2019~) | D38: law.go.kr 원문 (verify_*.md)
A39: §7 확정 | B39: 7.1 세율·세액 | C39: 증여세 세율 = 상속세 세율 준용(§56) | D39: law.go.kr 원문 (verify_*.md)
A40: §7 확정 | B40: 7.1 세율·세액 | C40: 계산 사례 12-1·12-2·12-3: verify_calc.py PASS (2026-08-12, 검증자 재실행 exit 0) | D40: law.go.kr 원문 (verify_*.md)
A41: §7 확정 | B41: 7.2 공제 | C41: 기초공제 2억(§18) · 일괄공제 5억 선택 구조 · 무신고 시 5억 자동(§21①) · 배우자 단독상속 시 일괄공제 배제(§21②) | D41: law.go.kr 원문 (verify_*.md)
A42: §7 확정 | B42: 7.2 공제 | C42: 인적공제 §20: 자녀 5천만(태아 포함, 2023~) · 미성년 1천만 × 19세까지 · 연로 65세 5천만 · 장애인 1천만 × 기대여명 + 중복 규칙 | D42: law.go.kr 원문 (verify_*.md)
A43: §7 확정 | B43: 7.2 공제 | C43: 배우자공제 §19: 최소 5억(④) · 최대 30억 · 분할기한은 신고기한 다음날부터 9개월(②) · 부득이한 사유 6개월 추가(③) | D43: law.go.kr 원문 (verify_*.md)
A44: §7 확정 | B44: 7.2 공제 | C44: 금융재산상속공제 §22: 2천만 초과 시 max(20%, 2천만), 2천만 이하 전액, 2억 한도, 거주자 한정. 범위는 시행령 §19① | D44: law.go.kr 원문 (verify_*.md)
A45: §7 확정 | B45: 7.2 공제 | C45: 동거주택상속공제 §23의2: 100%·6억 (40%·5억, 80%·5억은 구법). 특례 3단: 법 §23의2② → 령 §20의2② → 규칙 §9의2 | D45: law.go.kr 원문 (verify_*.md)
A46: §7 확정 | B46: 7.2 공제 | C46: 재해손실공제 §23: '재난' 정의는 시행령 §20① | D46: law.go.kr 원문 (verify_*.md)
...

Sheet ⑤ 조문 인용 색인
A1: 법령·조문 | B1: 등장 장 | C1: law.go.kr 대조 (기입) | D1: 비고
A2: 국세기본법 §18③ | B2: 02장
A3: 국세기본법 §26의2 | B3: 25장
A4: 국세기본법 §45 | B4: 25장
A5: 국세기본법 §47의3④ | B5: 23장
A6: 국세기본법 §47의4 | B6: 23장
A7: 민법 §1000 | B7: 03장
A8: 민법 §1004의2 | B8: 03장
A9: 민법 제1001조 | B9: 12장
A10: 민법 제1009조 | B10: 09장
A11: 상증세법 §35 | B11: 14, 16장
A12: 상증세법 §61 | B12: 22장
A13: 상증세법 §63 | B13: 22장
... A153: 조세특례제한법 §30의6 | B153: 19장

Sheet ⑥ 핵심 수치 30선
A1: 수치·규정 (책 기재) | B1: 근거 | C1: 장 | D1: law.go.kr 대조 (기입) | E1: 비고
A2: 세율표 10~50% + 누진공제 0/1천만/6천만/1.6억/4.6억 | B2: §26 | C2: 12장·부록C
A3: 기초공제 2억 / 일괄공제 5억 | B3: §18·§21 | C3: 8장
A4: 자녀 5천만·미성년 1천만×(19-나이)·연로 65세 5천만·장애인 1천만×기대여명 | B4: §20 | C4: 8장
A5: 배우자공제 최소 5억~최대 30억·분할기한 신고기한+9개월 | B5: §19 | C5: 9장
A6: 금융재산공제 max(20%,2천만)·한도 2억 | B6: §22 | C6: 10장
A7: 동거주택 100%·6억 | B7: §23의2 | C7: 10장
A8: 가업상속 300/400/600억·사후관리 5년·고용 90% | B8: §18의2 | C8: 11장
A9: 세대생략 할증 30%(미성년 20억↑ 40%) | B9: §27 | C9: 12장
A10: 신고세액공제 3% | B10: §69 | C10: 12장
A11: 추정상속재산 1년 2억/2년 5억·산입=미소명−min(20%,2억) | B11: §15·령§11 | C11: 5장
A12: 사전증여 합산 상속인 10년/그 외 5년 | B12: §13 | C12: 6장
A13: 장례비 500만 기본·1천만 한도+봉안 500만 | B13: §14·령§9 | C13: 7장
... A33: 유류분 개정 2026.2. (상실사유·가액반환) | B33: 민법 개정 | C33: 3장 ★법률번호 확인
