Workbook

Sheet ① 작업표
A1: 연번 | B1: 장 | C1: 절·위치 | D1: 우선순위 | E1: 확인 항목 (마커 원문) | F1: 확인해야 할 조문·출처 | G1: 확인 내용 (체크리스트) | H1: 원고 위치 | I1: 상태 | J1: 확인 결과 기재란 | K1: 근거 URL·법령버전 | L1: 확인자 | M1: 확인일 | N1: 비고 | O1: 키 | P1: 자동판정
A2: 1 | B2: 0 | C2: 그 밖의 표기 | D2: 🟢 보완 | E2: [검증필요 — 사유] | G2: 사유 | H2: 00_서문.md L49 | I2: 미확인 | O2: 0|L0049|1 | P2: 미확인
A3: 2 | B3: 0 | C3: 그 밖의 표기 | D3: 🟡 중요 | E3: [검증필요] | G3: 는 이 책의 약점이 아니라 신뢰의 근거다.** 확인하지 못한 것을 확인한 것처럼 쓰지 않고 그 자리에 표시해 둔다는 뜻이며, 독자에게는 그 항목만은 관할 관청이나 법령 원문으로 스스로 확인하라는 안내다. | H3: 00_서문.md L52 | I3: 미확인 | O3: 0|L0052|1 | P3: 미확인
A4: 3 | B4: 1 | C4: 1.1.3 연혁 | D4: 🟢 보완 | E4: [검증필요] | G4: . 2005년 개정으로 종합토지세가 폐지되고 토지분 재산세로 통합되었다 ` | H4: 01_보유세_전체그림.md L25 | I4: 미확인 | O4: 1|L0025|1 | P4: 미확인
A5: 4 | B5: 1 | C5: 1.1.3 연혁 | D5: 🟡 중요 | E5: [검증필요 — 개정 법률 호수·시행일] | G5: 개정 법률 호수·시행일 | H5: 01_보유세_전체그림.md L25 | I5: 미확인 | O5: 1|L0025|2 | P5: 미확인
A6: 5 | B6: 1 | C6: 1.3.1 과세기준일 6월 1일 | D6: 🟢 보완 | E6: [검증필요 — 입법 취지] | G6: 입법 취지 | H6: 01_보유세_전체그림.md L73 | I6: 미확인 | O6: 1|L0073|1 | P6: 미확인
A7: 6 | B7: 1 | C7: 1.5 자주 묻는 질문 | D7: 🔴 최우선 | E7: [검증필요 — 보통징수 재산세에 대한 경정청구 가부] | G7: 보통징수 재산세에 대한 경정청구 가부 | H7: 01_보유세_전체그림.md L204 | I7: 미확인 | O7: 1|L0204|1 | P7: 미확인
A8: 7 | B8: 2 | C8: (5) 주택과 부속토지 | D8: 🟢 보완 | E8: [검증필요] | G8: 판결문 원문 미대조). 주택 수 산정은 (→ 제9장)에서 다룬다. | H8: 02_재산세_과세대상.md L75 | I8: 미확인 | O8: 2|L0075|1 | P8: 미확인
A9: 8 | B9: 2 | C9: (6) 겸용주택 | D9: 🟡 중요 | E9: [검증필요] | G9: 제2호의2와 제106조 제3항의 신설 연월일은 확인되지 않았다. | H9: 02_재산세_과세대상.md L99 | I9: 미확인 | O9: 2|L0099|1 | P9: 미확인
A10: 9 | B10: 2 | C10: (1) 리딩 판례 | D10: 🟢 보완 | E10: [검증필요] | G10: 판결문 원문 미취득). ### (2) 사례 2-1: 1층은 가게, 3층은 살림집 — 겸용주택의 세 갈래 과세 가상의 사례이며, 실제 사안은 전문가 확인이 필요하다. | H10: 02_재산세_과세대상.md L154 | I10: 미확인 | O10: 2|L0154|1 | P10: 미확인
A11: 10 | B11: 2 | C11: (3) 사례 2-2: 건물을 철거하자 세부담이 증가한다 | D11: 🔴 최우선 | E11: [검증필요] | G11: 기준일·항 번호 미대조). ③ 제113조 제1항 단서(재산세 경감분의 과세표준 공제)를 매개로 그 부분이 분리과세 대상인지를 둘러싼 분쟁이 2021년 이후 계속되며 하급심 결론이 갈린다. | H11: 02_재산세_과세대상.md L229 | I11: 미확인 | O11: 2|L0229|1 | P11: 미확인
A12: 11 | B12: 2 | C12: (3) 사례 2-2: 건물을 철거하자 세부담이 증가한다 | D12: 🟢 보완 | E12: [검증필요] | G12: 이 판례군은 원문 미확보로 사건번호를 표기하지 않았다. | H12: 02_재산세_과세대상.md L231 | I12: 미확인 | O12: 2|L0231|1 | P12: 미확인
A13: 12 | B13: 3 | C13: 3.2.2 6월 1일 판정 | D13: 🟡 중요 | E13: [검증필요] | F13: 시행령 제20조 제2항 | G13: 계약상 잔금지급일과 사실상 잔금지급일이 다를 때 사실상 잔금지급일을 기준으로 판단한 조세심판원 결정례가 있다고 알려져 있으나 결정번호와 결정일자를 확인하지 못했다. 결론은 시행령 제20조 제2항만으로 완결된다. | H13: 03_재산세_납세의무자.md L48 | I13: 미확인 | O13: 3|L0048|1 | P13: 미확인
A14: 13 | B14: 3 | C14: 3.2.3 신탁재산 | D14: 🟢 보완 | E14: [검증필요] | G14: ) | H14: 03_재산세_납세의무자.md L56 | I14: 미확인 | O14: 3|L0056|1 | P14: 미확인
A15: 14 | B15: 3 | C15: 3.2.3 신탁재산 | D15: 🟢 보완 | E15: [검증필요 — 판결문 본문 미취득] | G15: 판결문 본문 미취득 | H15: 03_재산세_납세의무자.md L62 | I15: 미확인 | O15: 3|L0062|1 | P15: 미확인
A16: 15 | B16: 3 | C16: 3.4.3 판례 | D16: 🟢 보완 | E16: [검증필요] | F16: 대법원 2024. 3. 28. · 2024두30281 | G16: 과세기준일 이후 상속재산분할심판이 확정된 경우 그 소급효가 지나간 과세기준일의 판정을 바꿀 수 있는지가 다투어진 사건이 있다(대법원 2024. 3. 28. 선고 2024두30281 판결). 다만 심리불속행 기각이어서 실체 판단 이유가 판결문에 나타나지 않으며 원심 판결문도 확보하지 못했다. | H16: 03_재산세_납세의무자.md L147 | I16: 미확인 | O16: 3|L0147|1 | P16: 미확인
A17: 16 | B17: 4 | C17: 4.2.2 건축물에는 공시가격이 없다 | D17: 🔴 최우선 | E17: [검증필요] | G17: 기준가격·경과연수별 잔가율 등 세부 산정 기준은 행정안전부 기준의 영역이라 수치는 다루지 않는다. | H17: 04_재산세_과세표준.md L67 | I17: 미확인 | O17: 4|L0067|1 | P17: 미확인
A18: 17 | B18: 4 | C18: 4.2.2 건축물에는 공시가격이 없다 | D18: 🟢 보완 | E18: [검증필요] | G18: (사유 미기재 — 원고 확인 필요) | H18: 04_재산세_과세표준.md L68 | I18: 미확인 | O18: 4|L0068|1 | P18: 미확인
A19: 18 | B19: 4 | C19: 4.3.1 절차 총괄표 | D19: 🟢 보완 | E19: [검증필요] | G19: (사유 미기재 — 원고 확인 필요) | H19: 04_재산세_과세표준.md L152 | I19: 미확인 | O19: 4|L0152|1 | P19: 미확인
A20: 19 | B20: 4 | C20: 4.3.2 공시기준일이 달라지는 경우 | D20: 🟡 중요 | E20: [검증필요] | G20: "1~6월 중 지목변경된 토지의 새 개별공시지가는 그 해 6월 1일 과세에 반영되지 않는다"는 결론이 도출되는 듯하나 조문의 추론일 뿐 판례·예규로 확인한 명제가 아니다. 이 책은 "기준일이 달라 적용 연도가 어긋날 수 있다"까지만 서술한다. | H20: 04_재산세_과세표준.md L162 | I20: 미확인 | O20: 4|L0162|1 | P20: 미확인
A21: 20 | B21: 4 | C21: 4.3.3 계산 순서도 | D21: 🟡 중요 | E21: [검증필요] | G21: 위 순서는 조문의 문언을 배열한 것이며 "이 순서로 적용한다"고 명시한 조문· 판례를 확인한 것은 아니다. | H21: 04_재산세_과세표준.md L174 | I21: 미확인 | O21: 4|L0174|1 | P21: 미확인
A22: 21 | B22: 4 | C22: 4.3.3 계산 순서도 | D22: 🔴 최우선 | E22: [검증필요] | F22: §122 | G22: 세부담상한을 일반 재산세액과 도시지역분에 각각 따로 거는지 합산액에 한 번 거는지도 문제된다 — §122 본문이 "제112조 제1항 제1호·제2호 및 같은 조 제2항에 따른 각각의 세액"이라 정하므로 각각 따로 적용하는 구조로 읽히나 이를 확인한 판례를 취득하지 못했다. | H22: 04_재산세_과세표준.md L175 | I22: 미확인 | O22: 4|L0175|1 | P22: 미확인
A23: 22 | B23: 4 | C23: 사례 4-2 | D23: 🟢 보완 | E23: [검증필요] | G23: 위 (2)는 세부담상한의 적용 단위 쟁점을 피하려고 도시지역분을 넣지 않았다. | H23: 04_재산세_과세표준.md L248 | I23: 미확인 | O23: 4|L0248|1 | P23: 미확인
A24: 23 | B24: 4 | C24: 4.4.2 판례 | D24: 🟡 중요 | E24: [검증필요] | F24: 2012두11843 · 2007두13159 | G24: 2012두11843의 하자승계 법리는 원심의 판시이고 대법원은 심리불속행 기각으로 확정하였을 뿐이므로 "대법원이 판시하였다"고 써서는 안 되며, 원심이 인용한 2007두13159 · 95누10075는 사건번호만 기재한다. | H24: 04_재산세_과세표준.md L283 | I24: 미확인 | O24: 4|L0283|1 | P24: 미확인
A25: 24 | B25: 4 | C25: 4.4.2 판례 | D25: 🟢 보완 | E25: [검증필요] | G25: 93누8542는 국가법령정보센터로 원문을 확보하지 못했다. | H25: 04_재산세_과세표준.md L285 | I25: 미확인 | O25: 4|L0285|1 | P25: 미확인
A26: 25 | B26: 4 | C26: 4.4.2 판례 | D26: 🟢 보완 | E26: [검증필요] | F26: 2017두37253 · 2012두10086 · 2007두13180 | G26: 2017두37253의 원심이 원용한 2012두10086 · 2007두13180도 판결문 기재 형태로만 확인하였다. | H26: 04_재산세_과세표준.md L286 | I26: 미확인 | O26: 4|L0286|1 | P26: 미확인
A27: 26 | B27: 4 | C27: 4.4.2 판례 | D27: 🟢 보완 | E27: [검증필요] | F27: 2020두46301 · 2016두42395 · 2015두41890 | G27: 2020두46301은 심리불속행 여부를 확인하지 못했고, 2016두42395 · 2015두41890은 요지를 취득하지 못해 결론을 서술하지 않는다. | H27: 04_재산세_과세표준.md L287 | I27: 미확인 | O27: 4|L0287|1 | P27: 미확인
A28: 27 | B28: 5 | C28: 5.2.1 주택 | D28: 🟡 중요 | E28: [검증필요] | F28: 법률 제17769호 · §111의2 | G28: 부칙(법률 제17769호, 2020.12.29) 제2조는 §111의2 개정규정을 시행일부터 6년이 되는 날까지 성립한 납세의무에 한정한다. | H28: 05_재산세_세율.md L65 | I28: 미확인 | O28: 5|L0065|1 | P28: 미확인
A29: 28 | B29: 5 | C29: 5.2.2 건축물 | D29: 🟡 중요 | E29: [검증필요] | G29: 「남녀를 불문하며」가 삽입된 개정 시점·대통령령 호수는 확정하지 못했다. | H29: 05_재산세_세율.md L90 | I29: 미확인 | O29: 5|L0090|1 | P29: 미확인
A30: 29 | B30: 5 | C30: 5.2.4 세율을 「어느 단위」에 적용하는가 | D30: 🟡 중요 | E30: [검증필요] | F30: §113③ · §107① | G30: 이 순서는 §113③과 §107①을 결합해 도출한 것으로, 명시한 단일 조문은 확인하지 못했다. | H30: 05_재산세_세율.md L111 | I30: 미확인 | O30: 5|L0111|1 | P30: 미확인
A31: 30 | B31: 5 | C31: 5.3.1 조문의 순서에 따른 계산 흐름 | D31: 🟡 중요 | E31: [검증필요] | G31: 위 흐름은 각 조문의 문언을 배열한 것이며, 「이 순서로 계산한다」고 명시한 조문이나 판례를 확인한 것은 아니다. | H31: 05_재산세_세율.md L165 | I31: 미확인 | O31: 5|L0165|1 | P31: 미확인
A32: 31 | B32: 5 | C32: 5.3.2 ★ 주택은 세부담상한이 아니라 과세표준상한제다 | D32: 🟡 중요 | E32: [검증필요] | G32: 이 적용 단위는 조문 문언에서 도출한 해석이며 실무 취급과 대조하지 못했다. | H32: 05_재산세_세율.md L190 | I32: 미확인 | O32: 5|L0190|1 | P32: 미확인
A33: 32 | B33: 5 | C33: 5.3.2 ★ 주택은 세부담상한이 아니라 과세표준상한제다 | D33: 🟢 보완 | E33: [검증필요] | F33: §147② · §122 | G33: 소방분 지역자원시설세의 세부담상한 적용 여부 — §147②은 "§122 본문"만 준용해 주택 배제 단서가 따라오는지 불명확하다. | H33: 05_재산세_세율.md L192 | I33: 미확인 | O33: 5|L0192|1 | P33: 미확인
A34: 33 | B34: 5 | C34: 5.3.3 ★ 「표준세율로 계산한 세액」과 「실제 부과세액」의 구분 | D34: 🔴 최우선 | E34: [검증필요] | G34: 이 산식은 법령 원문이 이미지와 텍스트를 병기한 형태여서, 분자·분모 배치를 종이 법령집으로 최종 대조할 필요가 있다(→ 제13장에서 재확인). 📌 개정 예고 (확정 아님 · 2026-08 입법 진행 중) — 2026년 세제개편안은 종부세 기본공제 이원화 (실거주 14억 / 비거주 9억), 공정시 | H34: 05_재산세_세율.md L225 | I34: 미확인 | O34: 5|L0225|1 | P34: 미확인
A35: 34 | B35: 5 | C35: 5.3.3 ★ 「표준세율로 계산한 세액」과 「실제 부과세액」의 구분 | D35: 🔴 최우선 | E35: [검증필요] | G35: --- ## 5.4 판례·사례 ### 5.4.1 계산 사례 아래 세 사례는 verify_calc.py 기계 검산을 통과한 것이며 세율은 전부 법령 원문 확인분이다. | H35: 05_재산세_세율.md L231 | I35: 미확인 | O35: 5|L0231|1 | P35: 미확인
A36: 35 | B36: 5 | C36: 사례 5-2 · 고지서 한 장의 해부 | D36: 🟡 중요 | E36: [검증필요] | G36: 도시지역분·지방교육세·지역자원시설세도 7월·9월로 반분되는지는 조문으로 확정하지 못했다. | H36: 05_재산세_세율.md L286 | I36: 미확인 | O36: 5|L0286|1 | P36: 미확인
A37: 36 | B37: 5 | C37: 5.4.2 판례 | D37: 🟢 보완 | E37: [검증필요] | F37: 2019두56357 · 2023두47435 | G37: 2019두56357과 2023두47435의 결론이 갈린 이유는 확정하지 못했다. | H37: 05_재산세_세율.md L327 | I37: 미확인 | O37: 5|L0327|1 | P37: 미확인
A38: 37 | B38: 5 | C38: 5.4.2 판례 | D38: 🟡 중요 | E38: [검증필요] | F38: §106② | G38: §106②2의2 적용 시 세부담이 늘어나는지 줄어드는지는 조문에서 단정할 수 없다. | H38: 05_재산세_세율.md L328 | I38: 미확인 | O38: 5|L0328|1 | P38: 미확인
A39: 38 | B39: 5 | C39: 5.4.3 판례 | D39: 🟢 보완 | E39: [검증필요] | G39: 두 「미집행」을 같은 것으로 서술해서는 안 되며, 원용 가능성과 심리불속행 여부도 미확정이다. | H39: 05_재산세_세율.md L353 | I39: 미확인 | O39: 5|L0353|1 | P39: 미확인
A40: 39 | B40: 5 | C40: 5.4.3 판례 | D40: 🟡 중요 | E40: [검증필요] | F40: 2007두10303 · 2017두59154 · 2012두17568 | G40: 2007두10303(2017두59154 원심 인용)은 원문 미취득으로 사건번호만 기재하며, 2012두17568의 심리불속행 여부도 확인하지 못했다. | H40: 05_재산세_세율.md L356 | I40: 미확인 | O40: 5|L0356|1 | P40: 미확인
...

Sheet ② 요약
A1: 원문 대조 진행 현황
A2: 상태 열(① 작업표 I열)을 채우면 아래 수치·진행률이 자동으로 갱신된다.
A4: ■ 전체
A5: 총 등재 건수 | C5: =COUNTA('① 작업표'!$A$2:$A$2000)
A6: 확인완료 | C6: =COUNTIF('① 작업표'!$I$2:$I$2000,"확인완료")
A7: 확인중 | C7: =COUNTIF('① 작업표'!$I$2:$I$2000,"확인중")
A8: 미확인 | C8: =COUNTIF('① 작업표'!$I$2:$I$2000,"미확인")
A9: 수정필요 | C9: =COUNTIF('① 작업표'!$I$2:$I$2000,"수정필요")
A10: 해당없음(표기용) | C10: =COUNTIF('① 작업표'!$I$2:$I$2000,"해당없음")
A11: 전체 진행률 | C11: =IFERROR(COUNTIF('① 작업표'!$I$2:$I$2000,"확인완료")/(COUNTA('① 작업표'!$A$2:$A$2000)-COUNTIF('① 작업표'!$I$2:$I$2000,"해당없음")),"") | J11: 분모는 ⚪ 표기용 10건을 뺀 실제 검증 대상 기준
A12: 🔴 최우선 진행률 | C12: =IFERROR(COUNTIFS('① 작업표'!$D$2:$D$2000,"🔴 최우선",'① 작업표'!$I$2:$I$2000,"확인완료")/COUNTIF('① 작업표'!$D$2:$D$2000,"🔴 최우선"),"") | J12: 🔴은 어떤 경우에도 미해소 상태로 출판하지 말 것 (체크리스트 §0.2)
A14: ■ 우선순위별
A15: 우선순위 | B15: 기준 — 틀렸을 때의 결과 | C15: 등재 | D15: 확인완료 | E15: 확인중 | F15: 미확인 | G15: 수정필요 | H15: 해당없음 | I15: 진행률
A16: 🔴 최우선 | B16: 금액·세율·한도·비율·요건 연수·산식 — 세액이 틀어진다 | C16: =COUNTIF('① 작업표'!$D$2:$D$2000,"🔴 최우선") | D16: =COUNTIFS('① 작업표'!$D$2:$D$2000,"🔴 최우선",'① 작업표'!$I$2:$I$2000,"확인완료") | E16: =COUNTIFS('① 작업표'!$D$2:$D$2000,"🔴 최우선",'① 작업표'!$I$2:$I$2000,"확인중") | F16: =COUNTIFS('① 작업표'!$D$2:$D$2000,"🔴 최우선",'① 작업표'!$I$2:$I$2000,"미확인") | G16: =COUNTIFS('① 작업표'!$D$2:$D$2000,"🔴 최우선",'① 작업표'!$I$2:$I$2000,"수정필요") | H16: =COUNTIFS('① 작업표'!$D$2:$D$2000,"🔴 최우선",'① 작업표'!$I$2:$I$2000,"해당없음") | I16: =IFERROR(D16/(C16-H16),"")
A17: 🟡 중요 | B17: 조문번호·항·호 배치, 법문 축자 표현, 준용 관계 — 인용이 틀린다 | C17: =COUNTIF('① 작업표'!$D$2:$D$2000,"🟡 중요") | D17: =COUNTIFS('① 작업표'!$D$2:$D$2000,"🟡 중요",'① 작업표'!$I$2:$I$2000,"확인완료") | E17: =COUNTIFS('① 작업표'!$D$2:$D$2000,"🟡 중요",'① 작업표'!$I$2:$I$2000,"확인중") | F17: =COUNTIFS('① 작업표'!$D$2:$D$2000,"🟡 중요",'① 작업표'!$I$2:$I$2000,"미확인") | G17: =COUNTIFS('① 작업표'!$D$2:$D$2000,"🟡 중요",'① 작업표'!$I$2:$I$2000,"수정필요") | H17: =COUNTIFS('① 작업표'!$D$2:$D$2000,"🟡 중요",'① 작업표'!$I$2:$I$2000,"해당없음") | I17: =IFERROR(D17/(C17-H17),"")
A18: 🟢 보완 | B18: 예규·판례 사건번호, 서식 명칭, 절차·통계 — 신뢰도가 깎인다 | C18: =COUNTIF('① 작업표'!$D$2:$D$2000,"🟢 보완") | D18: =COUNTIFS('① 작업표'!$D$2:$D$2000,"🟢 보완",'① 작업표'!$I$2:$I$2000,"확인완료") | E18: =COUNTIFS('① 작업표'!$D$2:$D$2000,"🟢 보완",'① 작업표'!$I$2:$I$2000,"확인중") | F18: =COUNTIFS('① 작업표'!$D$2:$D$2000,"🟢 보완",'① 작업표'!$I$2:$I$2000,"미확인") | G18: =COUNTIFS('① 작업표'!$D$2:$D$2000,"🟢 보완",'① 작업표'!$I$2:$I$2000,"수정필요") | H18: =COUNTIFS('① 작업표'!$D$2:$D$2000,"🟢 보완",'① 작업표'!$I$2:$I$2000,"해당없음") | I18: =IFERROR(D18/(C18-H18),"")
A19: ⚪ 표기 | B19: 표기 설명·상호참조 — 원문 조회 대상이 아니며 마커를 지우지 말 것 | C19: =COUNTIF('① 작업표'!$D$2:$D$2000,"⚪ 표기") | D19: =COUNTIFS('① 작업표'!$D$2:$D$2000,"⚪ 표기",'① 작업표'!$I$2:$I$2000,"확인완료") | E19: =COUNTIFS('① 작업표'!$D$2:$D$2000,"⚪ 표기",'① 작업표'!$I$2:$I$2000,"확인중") | F19: =COUNTIFS('① 작업표'!$D$2:$D$2000,"⚪ 표기",'① 작업표'!$I$2:$I$2000,"미확인") | G19: =COUNTIFS('① 작업표'!$D$2:$D$2000,"⚪ 표기",'① 작업표'!$I$2:$I$2000,"수정필요") | H19: =COUNTIFS('① 작업표'!$D$2:$D$2000,"⚪ 표기",'① 작업표'!$I$2:$I$2000,"해당없음") | I19: =IFERROR(D19/(C19-H19),"")
A21: ■ 장별
A22: 장 | B22: 제목(약칭) | C22: 마커 | D22: 🔴 | E22: 🟡 | F22: 🟢 | G22: ⚪ | H22: 확인완료 | I22: 진행률 | J22: 집중 검증 권고
A23: 합계 | C23: =SUM(C23:C22) | D23: =SUM(D23:D22) | E23: =SUM(E23:E22) | F23: =SUM(F23:F22) | G23: =SUM(G23:G22) | H23: =SUM(H23:H22) | I23: =IFERROR(H23/(C23-G23),"")
A25: ■ 집중 검증 권고 장 — 여기부터 시작하라 (체크리스트 §0.4)
A26: 상태 | B26: 우선순위 | C26: 내용
A28: ■ 전 장 공통 — 1회 스캔으로 끝내는 작업 (체크리스트 §0.5)
A29: 상태 | B29: 우선순위 | C29: 내용
A31: ■ 보완 과제 — 마커 외 (체크리스트 §4)
A32: 상태 | B32: 우선순위 | C32: 내용
A34: ■ 개정 감시 항목 — 매 세션·매 개정판 재확인 (체크리스트 §2)
A35: 출판 직전 이 블록을 다시 돌릴 것. 검증 시점과 출판 시점 사이에 개정이 끼면 검증 결과는 무효가 된다.
A36: 상태 | B36: 우선순위 | C36: 내용

Sheet ③ 확인 방법
A1: 절 | B1: 구분 | C1: 내용 / URL / 값

Sheet ④ 확인 완료 이력
A1: 구분 | B1: 분류 | C1: 확정 사항 — 재검증 대상 아님 | D1: 출처 | E1: 비고
A2: 여기 적힌 것은 원문 대조가 끝난 사실이다. 원고가 이와 다르게 쓰고 있다면 원고가 틀린 것이다. 재검토 시 중복 작업을 막는 용도.
A3: ■ 근거 파일 — 05_review/verify_*.md (1차 출처 취득 성공분)
A5: ■ verify 확정 사항 — 원고 반영 확인 대상 (체크리스트 §3)
A7: ■ 확인 완료 — 그대로 사용 가능한 사실 (체크리스트 §7)
A9: ■ 기존 체크리스트에서 해소된 항목 (체크리스트 §6 — 이력)
