Workbook

Sheet 00_입력
A1: 파주 축현리 도시개발사업 — 입력 변수
A3: ■ 사업 개요
A4: 구분 | B4: 항목 | C4: 값 | D4: 단위 | E4: 비고
A5: 사업 | B5: 사업유형 | C5: 민간 자체시행 — 도시개발사업(수용·사용방식) | E5: 정비사업 / 민간 자체시행
B6: 소재지 | C6: 경기도 파주시 탄현면 축현리 608-5번지 일원 | E6: 조례·분양가상한제 확인 대상
A7: 규모 | B7: 대지면적 | C7: 127181 | D7: ㎡
B8: 대지면적(평) | C8: =C7*0.3025 -> 38472.253 | D8: 평 | E8: ㎡ × 0.3025 자동환산
B9: 지상연면적 | C9: 274339.68 | D9: ㎡
B10: 지상연면적(평) | C10: =C9*0.3025 -> 82987.753 | D10: 평 | E10: ㎡ × 0.3025 자동환산
B11: 지하연면적 | C11: 132349.85 | D11: ㎡
B12: 연면적 합계(평) | C12: =(C9+C11)*0.3025 -> 123023.58 | D12: 평 | E12: (지상+지하) × 0.3025 자동환산
B13: 건폐율 | C13: 0.2237
B14: 용적률 | C14: 2.1571
B15: 세대수 | C15: 2495 | D15: 세대
B16: 주차대수 | C16: 3617 | D16: 대
A18: ■ 사업 기간
A19: 구분 | B19: 항목 | C19: 값 | D19: 단위 | E19: 비고
A20: 기간 | B20: 인허가 기간 | C20: 57 | D20: 개월 | E20: 표준 일정
B21: 공사 기간 | C21: 54 | D21: 개월
B22: 분양~정산 기간 | C22: 6 | D22: 개월
B23: 지연 버퍼 | C23: 9 | D23: 개월 | E23: ★ 별도 계상 — 은폐 금지
B24: 총 사업기간 | C24: =SUM(C20:C23) -> 126 | D24: 개월
A26: ■ 금융 조건
A27: 구분 | B27: 항목 | C27: 값 | D27: 단위 | E27: 비고
B28: 자기자본(Equity) | C28: 346100000 | D28: 천원
B29: 본PF 통합(Tr.A 선순위+Tr.B 중순위+Tr.C 후순위) 한도 | C29: 690000000 | D29: 천원
B30: 본PF 통합(Tr.A 선순위+Tr.B 중순위+Tr.C 후순위) 금리 | C30: 0.0835
B31: 본PF 통합(Tr.A 선순위+Tr.B 중순위+Tr.C 후순위) 취급수수료 | C31: 0.0146
B32: 브릿지(토지담보) 한도 | C32: 52000000 | D32: 천원
B33: 브릿지(토지담보) 금리 | C33: 0.12
B34: 브릿지(토지담보) 취급수수료 | C34: 0.02
A36: ■ 분양 대금 납입 구조
A37: 구분 | B37: 항목 | C37: 값 | D37: 단위 | E37: 비고
B38: 계약금 비율 | C38: 0.1
B39: 중도금 차수 | C39: 6 | E39: 회
B40: 중도금 회차별 비율 | C40: 0.1
B41: 잔금 비율 | C41: 0.3
B42: 적립계좌 비율(준공전) | C42: 1 | E42: 대출 상환 재원
B43: 적립계좌 비율(준공후) | C43: 1
A45: ※ 노란색 셀만 수정하십시오. 나머지는 수식으로 연결되어 자동 재계산됩니다.

Sheet 01_사업수지
A1: 파주 축현리 도시개발사업 — 사업수지
A2: (단위: 천원, VAT 별도)
A4: ■ 수입
A5: 구분 | B5: 세부 | C5: 분양면적(평) | D5: 평당분양가 | E5: 수입액 | F5: 구성비 | G5: 비고
A6: 주거 | B6: 전용 59㎡ (25평형) 457세대 | C6: 11585.1 | D6: 13500 | E6: =C6*D6 -> 156398850 | F6: =IFERROR(E6/$E$13,0) -> 0.14123374 | G6: SSOT §3 기준 시나리오 1,350만원/평 (면적기준 안분)
A7: 주거 | B7: 전용 74㎡ (30평형) 241세대 | C7: 7331.3 | D7: 13500 | E7: =C7*D7 -> 98972550 | F7: =IFERROR(E7/$E$13,0) -> 0.08937574 | G7: SSOT §3 기준 시나리오 1,350만원/평 (면적기준 안분)
A8: 주거 | B8: 전용 84㎡ (34평형) 1,747세대 | C8: 60230.1 | D8: 13500 | E8: =C8*D8 -> 813106350 | F8: =IFERROR(E8/$E$13,0) -> 0.73426402 | G8: SSOT §3 기준 시나리오 1,350만원/평 (면적기준 안분)
A9: 주거 | B9: 전용 110㎡ (45평형) 50세대 | C9: 2281.5 | D9: 13500 | E9: =C9*D9 -> 30800250 | F9: =IFERROR(E9/$E$13,0) -> 0.027813724 | G9: SSOT §3 기준 시나리오 1,350만원/평 (면적기준 안분)
A10: 근생 | B10: 근린생활시설 1,799㎡ | C10: 544 | D10: 12000 | E10: =C10*D10 -> 6528000 | F10: =IFERROR(E10/$E$13,0) -> 0.0058950167 | G10: [가정] sales-analyst §4-1 — 실적 미조회
B11: 분양 총액 | C11: =SUM(C6:C10) -> 81972 | E11: =SUM(E6:E10) -> 1105806000
B12: VAT | E12: 1570000
B13: 수입 총계 | E13: =E11+E12 -> 1107376000
A15: ■ 지출
A16: 분류 | B16: 항목 | C16: 산출근거 | D16: 수량 | E16: 단가·요율 | F16: 구성비 | G16: 신뢰도 | H16: 금액 | I16: 기투입(Equity) | J16: 필수(PF) | K16: 분양불 | L16: 준공후불
A17: 토지비 | B17: 토지매입비 | C17: 55,241평 × 1,200천원/평 | D17: 55241 | E17: 1200 | G17: [가정] 2024 워크북 값 — 2026 재검증 필요 | H17: =D17*E17 -> 66289200 | I17: 0 | J17: =($H17-$I17)*1 -> 66289200 | K17: =($H17-$I17)*0 -> 0 | L17: =($H17-$I17)*0 -> 0
B18: 토지비 지가상승분 | C18: 토지매입비 × 연2.5% × 5년 (2026→2031 보상기준시점) | G18: [가정] 연 2.5% | H18: 8710945 | I18: 0 | J18: =($H18-$I18)*1 -> 8710945 | K18: =($H18-$I18)*0 -> 0 | L18: =($H18-$I18)*0 -> 0
B19: 취득세·지방교육세·농특세 | C19: 토지취득가 × 4.6% | G19: 법정요율 | H19: 3450007 | I19: 0 | J19: =($H19-$I19)*1 -> 3450007 | K19: =($H19-$I19)*0 -> 0 | L19: =($H19-$I19)*0 -> 0
B20: 법무사·등기 수수료 | C20: 토지취득가 × 0.2% | G20: 관행 | H20: 150000 | I20: 0 | J20: =($H20-$I20)*1 -> 150000 | K20: =($H20-$I20)*0 -> 0 | L20: =($H20-$I20)*0 -> 0
B21: 지주작업 용역비 | C21: 정액 | G21: [가정] 2024 워크북 | H21: 1500000 | I21: 0 | J21: =($H21-$I21)*1 -> 1500000 | K21: =($H21-$I21)*0 -> 0 | L21: =($H21-$I21)*0 -> 0
B22: 감정평가·보상업무 위탁비 | C22: 토지취득가 × 2.0% (수용방식 보상 위탁) | G22: [가정] 관행 | H22: 1500003 | I22: 0 | J22: =($H22-$I22)*1 -> 1500003 | K22: =($H22-$I22)*0 -> 0 | L22: =($H22-$I22)*0 -> 0
B23: 지장물·영업손실·이전보상 | C23: 창고·목장용지 25,868㎡ 대상 | G23: [가정] 실사 필요 | H23: 5000000 | I23: 0 | J23: =($H23-$I23)*1 -> 5000000 | K23: =($H23-$I23)*0 -> 0 | L23: =($H23-$I23)*0 -> 0
B24: 지목변경 간주취득세 | C24: 조성 준공 시 지목변경 (지방세법 제7조 제4항) — 과표 [가정] 800억 × 2.2% | G24: ★ tax-accountant 신규 계상 | H24: 1760000 | I24: 0 | J24: =($H24-$I24)*1 -> 1760000 | K24: =($H24-$I24)*0 -> 0 | L24: =($H24-$I24)*0 -> 0
B25: 국공유지 매입비 | C25: 구역 내 국공유지 면적 미상 — 토지조서 필요 | G25: [미산정] permit-navigator §4-4 | H25: 0 | I25: 0 | J25: =($H25-$I25)*1 -> 0 | K25: =($H25-$I25)*0 -> 0 | L25: =($H25-$I25)*0 -> 0
B26: 토지비 소계 | F26: =IFERROR(H26/$H$71,0) -> 0.050916471 | H26: =SUM(H17:H25) -> 88360155 | I26: =SUM(I17:I25) -> 0 | J26: =SUM(J17:J25) -> 88360155 | K26: =SUM(K17:K25) -> 0 | L26: =SUM(L17:L25) -> 0
A27: 건축비 | B27: 도급공사비(주택) | C27: 연면적 123,024평 × 7,000천원/평 | D27: 123024 | E27: 7000 | G27: SSOT §2 — 4방향 벤치마크 교차검증 | H27: =D27*E27 -> 861168000 | I27: 0 | J27: =($H27-$I27)*0.9 -> 775051200 | K27: =($H27-$I27)*0 -> 0 | L27: =($H27-$I27)*0.1 -> 86116800
B28: ★ 공사비 물가상승분 | C28: 도급공사비 × 연3% × 6년 (19.4%) — 착공 2033.08 | G28: [가정] 건설공사비지수 — 차단2 필수 | H28: 167111628 | I28: 0 | J28: =($H28-$I28)*0.9 -> 1.5040047e+08 | K28: =($H28-$I28)*0 -> 0 | L28: =($H28-$I28)*0.1 -> 16711163
B29: ★ 부지조성공사비(절·성토·기반시설) | C29: 구역 184,660㎡ × 150천원/㎡ | D29: 184660 | E29: 150 | G29: [가정] 임야36.2%·농지49.0% — 견적 필요 | H29: =D29*E29 -> 27699000 | I29: 0 | J29: =($H29-$I29)*1 -> 27699000 | K29: =($H29-$I29)*0 -> 0 | L29: =($H29-$I29)*0 -> 0
B30: 진입도로 개설비 | C30: 정액 | G30: [가정] 2024 워크북 | H30: 10000000 | I30: 0 | J30: =($H30-$I30)*1 -> 10000000 | K30: =($H30-$I30)*0 -> 0 | L30: =($H30-$I30)*0 -> 0
B31: 지장물 철거·석면조사 | C31: 정액 | G31: [가정] 2024 워크북 | H31: 3000000 | I31: 0 | J31: =($H31-$I31)*1 -> 3000000 | K31: =($H31-$I31)*0 -> 0 | L31: =($H31-$I31)*0 -> 0
B32: 인입공사분담금(전기·통신·가스) | C32: 정액 | G32: SSOT §5 | H32: 7400000 | I32: 0 | J32: =($H32-$I32)*1 -> 7400000 | K32: =($H32-$I32)*0 -> 0 | L32: =($H32-$I32)*0 -> 0
B33: 미술작품 설치비 | C33: 문화예술진흥법 — 건축비 연동 | G33: [가정] 2024 워크북 — 요율 확인 필요 | H33: 1500000 | I33: 0 | J33: =($H33-$I33)*1 -> 1500000 | K33: =($H33-$I33)*0 -> 0 | L33: =($H33-$I33)*0 -> 0
B34: 건축설계비 | C34: 정액 | G34: SSOT §5 | H34: 7400000 | I34: 0 | J34: =($H34-$I34)*1 -> 7400000 | K34: =($H34-$I34)*0 -> 0 | L34: =($H34-$I34)*0 -> 0
B35: CM·감리비 | C35: 정액 | G35: SSOT §5 | H35: 11100000 | I35: 0 | J35: =($H35-$I35)*1 -> 11100000 | K35: =($H35-$I35)*0 -> 0 | L35: =($H35-$I35)*0 -> 0
B36: 지질조사·측량·토목설계 | C36: 정액 | G36: [가정] | H36: 2000000 | I36: 0 | J36: =($H36-$I36)*1 -> 2000000 | K36: =($H36-$I36)*0 -> 0 | L36: =($H36-$I36)*0 -> 0
B37: 영향평가 용역(교통·소규모환경·재해) | C37: 3종 | G37: SSOT §5 | H37: 2000000 | I37: 0 | J37: =($H37-$I37)*1 -> 2000000 | K37: =($H37-$I37)*0 -> 0 | L37: =($H37-$I37)*0 -> 0
B38: 매장유산 지표조사 | C38: 사업면적 3만㎡ 이상 → 대상 | G38: [가정] 발굴 전환 시 예비비 충당 | H38: 500000 | I38: 0 | J38: =($H38-$I38)*1 -> 500000 | K38: =($H38-$I38)*0 -> 0 | L38: =($H38-$I38)*0 -> 0
B39: 도시개발 인허가 용역(개발계획·실시계획·지구단위) | C39: 정액 | G39: [가정] | H39: 3000000 | I39: 0 | J39: =($H39-$I39)*1 -> 3000000 | K39: =($H39-$I39)*0 -> 0 | L39: =($H39-$I39)*0 -> 0
B40: 건물 보존등기비(원시취득 취득세 등) | C40: 건축공사비(물가포함) × 3.16% | G40: 법정요율 — tax-accountant 확정 대기 | H40: 32493636 | I40: 0 | J40: =($H40-$I40)*0 -> 0 | K40: =($H40-$I40)*0 -> 0 | L40: =($H40-$I40)*1 -> 32493636
B41: 건축비 소계 | F41: =IFERROR(H41/$H$71,0) -> 0.65482078 | H41: =SUM(H27:H40) -> 1136372264 | I41: =SUM(I27:I40) -> 0 | J41: =SUM(J27:J40) -> 1.0010507e+09 | K41: =SUM(K27:K40) -> 0 | L41: =SUM(L27:L40) -> 1.353216e+08
A42: 부대비용 | B42: 시행사 일반관리비 | C42: 126개월 × 250,000천원/월 | D42: 126 | E42: 250000 | G42: [가정] 연 30억 | H42: =D42*E42 -> 31500000 | I42: 0 | J42: =($H42-$I42)*1 -> 31500000 | K42: =($H42-$I42)*0 -> 0 | L42: =($H42-$I42)*0 -> 0
...

Sheet 02_현금흐름
A1: 파주 축현리 도시개발사업 — 월별 현금흐름
A3: 구분 | B3: 항목 | C3: 총액 | D3: 1개월차 | E3: 2개월차 | F3: 3개월차 | G3: 4개월차 | H3: 5개월차 | I3: 6개월차 | J3: 7개월차 | K3: 8개월차 | L3: 9개월차 | M3: 10개월차 | N3: 11개월차 | O3: 12개월차 | P3: 13개월차 | Q3: 14개월차 | R3: 15개월차 | S3: 16개월차 | T3: 17개월차 | U3: 18개월차 | V3: 19개월차 | W3: 20개월차 | X3: 21개월차 | Y3: 22개월차 | Z3: 23개월차 | AA3: 24개월차 | AB3: 25개월차 | AC3: 26개월차 | AD3: 27개월차 | AE3: 28개월차 | AF3: 29개월차 | AG3: 30개월차 | AH3: 31개월차 | AI3: 32개월차 | AJ3: 33개월차 | AK3: 34개월차 | AL3: 35개월차 | AM3: 36개월차 | AN3: 37개월차 | AO3: 38개월차 | AP3: 39개월차 | AQ3: 40개월차 | AR3: 41개월차 | AS3: 42개월차 | AT3: 43개월차 | AU3: 44개월차 | AV3: 45개월차 | AW3: 46개월차 | AX3: 47개월차 | AY3: 48개월차 | AZ3: 49개월차 | BA3: 50개월차 | BB3: 51개월차 | BC3: 52개월차 | BD3: 53개월차 | BE3: 54개월차 | BF3: 55개월차 | BG3: 56개월차 | BH3: 57개월차 | BI3: 58개월차 | BJ3: 59개월차 | BK3: 60개월차 | BL3: 61개월차 | BM3: 62개월차 | BN3: 63개월차 | BO3: 64개월차 | BP3: 65개월차 | BQ3: 66개월차 | BR3: 67개월차 | BS3: 68개월차 | BT3: 69개월차 | BU3: 70개월차 | BV3: 71개월차 | BW3: 72개월차 | BX3: 73개월차 | BY3: 74개월차 | BZ3: 75개월차 | CA3: 76개월차 | CB3: 77개월차 | CC3: 78개월차 | CD3: 79개월차 | CE3: 80개월차 | CF3: 81개월차 | CG3: 82개월차 | CH3: 83개월차 | CI3: 84개월차 | CJ3: 85개월차 | CK3: 86개월차 | CL3: 87개월차 | CM3: 88개월차 | CN3: 89개월차 | CO3: 90개월차 | CP3: 91개월차 | CQ3: 92개월차 | CR3: 93개월차 | CS3: 94개월차 | CT3: 95개월차 | CU3: 96개월차 | CV3: 97개월차 | CW3: 98개월차 | CX3: 99개월차 | CY3: 100개월차 | CZ3: 101개월차 | DA3: 102개월차 | DB3: 103개월차 | DC3: 104개월차 | DD3: 105개월차 | DE3: 106개월차 | DF3: 107개월차 | DG3: 108개월차 | DH3: 109개월차 | DI3: 110개월차 | DJ3: 111개월차 | DK3: 112개월차 | DL3: 113개월차 | DM3: 114개월차 | DN3: 115개월차 | DO3: 116개월차 | DP3: 117개월차 | DQ3: 118개월차 | DR3: 119개월차 | DS3: 120개월차 | DT3: 121개월차 | DU3: 122개월차 | DV3: 123개월차 | DW3: 124개월차 | DX3: 125개월차 | DY3: 126개월차 | DZ3: Total | EA3: 검증
A4: 진행률 드라이버
B5: 공정률 | D5: 7.333e-05 | E5: 7.333e-05 | F5: 7.333e-05 | G5: 7.333e-05 | H5: 7.333e-05 | I5: 7.333e-05 | J5: 7.333e-05 | K5: 7.333e-05 | L5: 7.333e-05 | M5: 7.333e-05 | N5: 7.333e-05 | O5: 7.333e-05 | P5: 7.333e-05 | Q5: 7.333e-05 | R5: 7.333e-05 | S5: 7.333e-05 | T5: 7.333e-05 | U5: 7.333e-05 | V5: 7.333e-05 | W5: 0.00051333 | X5: 7.333e-05 | Y5: 7.333e-05 | Z5: 7.333e-05 | AA5: 7.333e-05 | AB5: 0.00020872 | AC5: 0.00020872 | AD5: 0.00020872 | AE5: 0.00020872 | AF5: 0.00020872 | AG5: 0.00020872 | AH5: 0.00020872 | AI5: 0.00020872 | AJ5: 0.00020872 | AK5: 0.00020872 | AL5: 0.00020872 | AM5: 0.00020872 | AN5: 0.00013538 | AO5: 0.00051844 | AP5: 0.00051844 | AQ5: 0.00051844 | AR5: 0.00051844 | AS5: 0.00051844 | AT5: 0.00051844 | AU5: 0.00051844 | AV5: 0.00051844 | AW5: 0.00051844 | AX5: 0.00051844 | AY5: 0.00051844 | AZ5: 0.00051844 | BA5: 0.00051844 | BB5: 0.00038306 | BC5: 0.00038306 | BD5: 0.00038306 | BE5: 0.00038306 | BF5: 0 | BG5: 0 | BH5: 0 | BI5: 0 | BJ5: 0 | BK5: 0 | BL5: 0 | BM5: 0 | BN5: 0 | BO5: 0 | BP5: 0 | BQ5: 0 | BR5: 0.00167317 | BS5: 0.00167317 | BT5: 0.00167317 | BU5: 0.00167317 | BV5: 0.00167317 | BW5: 0.00167317 | BX5: 0.00167317 | BY5: 0.00167317 | BZ5: 0.00167317 | CA5: 0.00167317 | CB5: 0.00167317 | CC5: 0.00167317 | CD5: 0.00167317 | CE5: 0.00167317 | CF5: 0.00167317 | CG5: 0.00167317 | CH5: 0.00167317 | CI5: 0.00167317 | CJ5: 0.0065121 | CK5: 0.01135103 | CL5: 0.01618995 | CM5: 0.02102888 | CN5: 0.0258678 | CO5: 0.03070673 | CP5: 0.03405337 | CQ5: 0.0388923 | CR5: 0.0388923 | CS5: 0.0388923 | CT5: 0.0388923 | CU5: 0.0388923 | CV5: 0.0388923 | CW5: 0.0388923 | CX5: 0.0388923 | CY5: 0.0388923 | CZ5: 0.0388923 | DA5: 0.0388923 | DB5: 0.0388923 | DC5: 0.0388923 | DD5: 0.0388923 | DE5: 0.03405337 | DF5: 0.02921444 | DG5: 0.02437552 | DH5: 0.02437552 | DI5: 0.02024859 | DJ5: 0.02024859 | DK5: 0.01540966 | DL5: 0.01540966 | DM5: 0.01057073 | DN5: 0.01057073 | DO5: 0.01057073 | DP5: 0.00573181 | DQ5: 0.00573181 | DR5: 0.00573181 | DS5: 0.03432599 | DT5: 0 | DU5: 0 | DV5: 0 | DW5: 0 | DX5: 0 | DY5: 2e-08 | DZ5: =SUM(D5:DY5) -> 1
B6: 공정률 누계 | D6: =D5 -> 7.333e-05 | E6: =D6+E5 -> 0.00014666 | F6: =E6+F5 -> 0.00021999 | G6: =F6+G5 -> 0.00029332 | H6: =G6+H5 -> 0.00036665 | I6: =H6+I5 -> 0.00043998 | J6: =I6+J5 -> 0.00051331 | K6: =J6+K5 -> 0.00058664 | L6: =K6+L5 -> 0.00065997 | ... DY6: =DX6+DY5 -> 1
B7: 분양률 | D7: 0 | E7: 0 | F7: 0 | G7: 0 | H7: 0 | I7: 0 | J7: 0 | K7: 0 | L7: 0 | M7: 0 | N7: 0 | O7: 0 | P7: 0 | Q7: 0 | R7: 0 | S7: 0 | T7: 0 | U7: 0 | V7: 0 | W7: 0 | X7: 0 | Y7: 0 | Z7: 0 | AA7: 0 | AB7: 0 | AC7: 0 | AD7: 0 | AE7: 0 | AF7: 0 | AG7: 0 | AH7: 0 | AI7: 0 | AJ7: 0 | AK7: 0 | AL7: 0 | AM7: 0 | AN7: 0 | AO7: 0 | AP7: 0 | AQ7: 0 | AR7: 0 | AS7: 0 | AT7: 0 | AU7: 0 | AV7: 0 | AW7: 0 | AX7: 0 | AY7: 0 | AZ7: 0 | BA7: 0 | BB7: 0 | BC7: 0 | BD7: 0 | BE7: 0 | BF7: 0 | BG7: 0 | BH7: 0 | BI7: 0 | BJ7: 0 | BK7: 0 | BL7: 0 | BM7: 0 | BN7: 0 | BO7: 0 | BP7: 0 | BQ7: 0 | BR7: 0 | BS7: 0 | BT7: 0 | BU7: 0 | BV7: 0 | BW7: 0 | BX7: 0 | BY7: 0 | BZ7: 0 | CA7: 0 | CB7: 0 | CC7: 0 | CD7: 0 | CE7: 0 | CF7: 0 | CG7: 0 | CH7: 0 | CI7: 0 | CJ7: 0.11333333 | CK7: 0.11333333 | CL7: 0.11333333 | CM7: 0.03666667 | CN7: 0.03666667 | CO7: 0.03666667 | CP7: 0.02 | CQ7: 0.02 | CR7: 0.02 | CS7: 0.02 | CT7: 0.02 | CU7: 0.02 | CV7: 0.01333333 | CW7: 0.01333333 | CX7: 0.01333333 | CY7: 0.01333333 | CZ7: 0.01333333 | DA7: 0.01333333 | DB7: 0.01333333 | DC7: 0.01333333 | DD7: 0.01333333 | DE7: 0.01333333 | DF7: 0.01333333 | DG7: 0.01333333 | DH7: 0.01666667 | DI7: 0.01666667 | DJ7: 0.01666667 | DK7: 0.01333333 | DL7: 0.01333333 | DM7: 0.01333333 | DN7: 0.02 | DO7: 0.02 | DP7: 0.02 | DQ7: 0.02 | DR7: 0.02 | DS7: 0.02 | DT7: 0.02 | DU7: 0.02 | DV7: 0.02 | DW7: 0 | DX7: 0 | DY7: 4e-08 | DZ7: =SUM(D7:DY7) -> 1
B8: 분양률 누계 | D8: =D7 -> 0 | E8: =D8+E7 -> 0 | F8: =E8+F7 -> 0 | G8: =F8+G7 -> 0 | H8: =G8+H7 -> 0 | I8: =H8+I7 -> 0 | J8: =I8+J7 -> 0 | K8: =J8+K7 -> 0 | L8: =K8+L7 -> 0 | ... DY8: =DX8+DY7 -> 1
A10: 수입
B11: 계약금 | C11: ='01_사업수지'!E11*0.1 -> 110580600 | D11: =$C11*D8 -> 0 | E11: =$C11*E7 -> 0 | F11: =$C11*F7 -> 0 | G11: =$C11*G7 -> 0 | H11: =$C11*H7 -> 0 | I11: =$C11*I7 -> 0 | J11: =$C11*J7 -> 0 | K11: =$C11*K7 -> 0 | L11: =$C11*L7 -> 0 | ... DY11: =$C11*DY7 -> 4.423224 | DZ11: =SUM(D11:DY11) -> 1.105806e+08 | EA11: =IF(ROUND(DZ11,0)<=ROUND(C11,0)+1,"OK","초과") -> OK
B12: 중도금 1차 | C12: ='01_사업수지'!E11*0.1 -> 110580600 | S12: =$C12*S8 -> 0 | T12: =$C12*T7 -> 0 | U12: =$C12*U7 -> 0 | V12: =$C12*V7 -> 0 | W12: =$C12*W7 -> 0 | X12: =$C12*X7 -> 0 | Y12: =$C12*Y7 -> 0 | Z12: =$C12*Z7 -> 0 | AA12: =$C12*AA7 -> 0 | ... DY12: =$C12*DY7 -> 4.423224 | DZ12: =SUM(D12:DY12) -> 1.105806e+08 | EA12: =IF(ROUND(DZ12,0)<=ROUND(C12,0)+1,"OK","초과") -> OK
B13: 중도금 2차 | C13: ='01_사업수지'!E11*0.1 -> 110580600 | AH13: =$C13*AH8 -> 0 | AI13: =$C13*AI7 -> 0 | AJ13: =$C13*AJ7 -> 0 | AK13: =$C13*AK7 -> 0 | AL13: =$C13*AL7 -> 0 | AM13: =$C13*AM7 -> 0 | AN13: =$C13*AN7 -> 0 | AO13: =$C13*AO7 -> 0 | AP13: =$C13*AP7 -> 0 | ... DY13: =$C13*DY7 -> 4.423224 | DZ13: =SUM(D13:DY13) -> 1.105806e+08 | EA13: =IF(ROUND(DZ13,0)<=ROUND(C13,0)+1,"OK","초과") -> OK
B14: 중도금 3차 | C14: ='01_사업수지'!E11*0.1 -> 110580600 | AW14: =$C14*AW8 -> 0 | AX14: =$C14*AX7 -> 0 | AY14: =$C14*AY7 -> 0 | AZ14: =$C14*AZ7 -> 0 | BA14: =$C14*BA7 -> 0 | BB14: =$C14*BB7 -> 0 | BC14: =$C14*BC7 -> 0 | BD14: =$C14*BD7 -> 0 | BE14: =$C14*BE7 -> 0 | ... DY14: =$C14*DY7 -> 4.423224 | DZ14: =SUM(D14:DY14) -> 1.105806e+08 | EA14: =IF(ROUND(DZ14,0)<=ROUND(C14,0)+1,"OK","초과") -> OK
B15: 중도금 4차 | C15: ='01_사업수지'!E11*0.1 -> 110580600 | BL15: =$C15*BL8 -> 0 | BM15: =$C15*BM7 -> 0 | BN15: =$C15*BN7 -> 0 | BO15: =$C15*BO7 -> 0 | BP15: =$C15*BP7 -> 0 | BQ15: =$C15*BQ7 -> 0 | BR15: =$C15*BR7 -> 0 | BS15: =$C15*BS7 -> 0 | BT15: =$C15*BT7 -> 0 | ... DY15: =$C15*DY7 -> 4.423224 | DZ15: =SUM(D15:DY15) -> 1.105806e+08 | EA15: =IF(ROUND(DZ15,0)<=ROUND(C15,0)+1,"OK","초과") -> OK
B16: 중도금 5차 | C16: ='01_사업수지'!E11*0.1 -> 110580600 | CA16: =$C16*CA8 -> 0 | CB16: =$C16*CB7 -> 0 | CC16: =$C16*CC7 -> 0 | CD16: =$C16*CD7 -> 0 | CE16: =$C16*CE7 -> 0 | CF16: =$C16*CF7 -> 0 | CG16: =$C16*CG7 -> 0 | CH16: =$C16*CH7 -> 0 | CI16: =$C16*CI7 -> 0 | ... DY16: =$C16*DY7 -> 4.423224 | DZ16: =SUM(D16:DY16) -> 1.105806e+08 | EA16: =IF(ROUND(DZ16,0)<=ROUND(C16,0)+1,"OK","초과") -> OK
B17: 중도금 6차 | C17: ='01_사업수지'!E11*0.1 -> 110580600 | CP17: =$C17*CP8 -> 51972882 | CQ17: =$C17*CQ7 -> 2211612 | CR17: =$C17*CR7 -> 2211612 | CS17: =$C17*CS7 -> 2211612 | CT17: =$C17*CT7 -> 2211612 | CU17: =$C17*CU7 -> 2211612 | CV17: =$C17*CV7 -> 1474407.6 | CW17: =$C17*CW7 -> 1474407.6 | CX17: =$C17*CX7 -> 1474407.6 | ... DY17: =$C17*DY7 -> 4.423224 | DZ17: =SUM(D17:DY17) -> 1.105806e+08 | EA17: =IF(ROUND(DZ17,0)<=ROUND(C17,0)+1,"OK","초과") -> OK
B18: 잔금 | C18: ='01_사업수지'!E11*0.3 -> 331741800 | DY18: =$C18*DY8 -> 3.317418e+08 | DZ18: =SUM(D18:DY18) -> 3.317418e+08 | EA18: =IF(ROUND(DZ18,0)<=ROUND(C18,0)+1,"OK","초과") -> OK
B19: 수입 계 | C19: =SUM(C11:C18) -> 1105806000 | D19: =SUM(D11:D18) -> 0 | E19: =SUM(E11:E18) -> 0 | F19: =SUM(F11:F18) -> 0 | G19: =SUM(G11:G18) -> 0 | H19: =SUM(H11:H18) -> 0 | I19: =SUM(I11:I18) -> 0 | J19: =SUM(J11:J18) -> 0 | ... DY19: =SUM(DY11:DY18) -> 3.3174183e+08 | DZ19: =SUM(D19:DY19) -> 1105806000
A21: 지출
B22: 토지비 | C22: ='01_사업수지'!H26 -> 88360155 | D22: =$C22 -> 88360155 | DZ22: =SUM(D22:DY22) -> 88360155 | EA22: =IF(ROUND(DZ22,0)=ROUND(C22,0),"OK","불일치") -> OK
B23: 건축비 | C23: ='01_사업수지'!H41 -> 1136372264 | D23: =$C23*D5 -> 83330.178 | E23: =$C23*E5 -> 83330.178 | F23: =$C23*F5 -> 83330.178 | G23: =$C23*G5 -> 83330.178 | H23: =$C23*H5 -> 83330.178 | I23: =$C23*I5 -> 83330.178 | J23: =$C23*J5 -> 83330.178 | K23: =$C23*K5 -> 83330.178 | ... DY23: =$C23*DY5 -> 22.727445 | DZ23: =SUM(D23:DY23) -> 1.1363723e+09 | EA23: =IF(ROUND(DZ23,0)=ROUND(C23,0),"OK","불일치") -> OK
B24: 부대비용 | C24: ='01_사업수지'!H63 -> 343741906 | D24: =$C24/126 -> 2728110.4 | E24: =$C24/126 -> 2728110.4 | F24: =$C24/126 -> 2728110.4 | G24: =$C24/126 -> 2728110.4 | H24: =$C24/126 -> 2728110.4 | I24: =$C24/126 -> 2728110.4 | J24: =$C24/126 -> 2728110.4 | K24: =$C24/126 -> 2728110.4 | ... DY24: =$C24/126 -> 2728110.4 | DZ24: =SUM(D24:DY24) -> 3.4374191e+08 | EA24: =IF(ROUND(DZ24,0)=ROUND(C24,0),"OK","불일치") -> OK
B25: 사업비 지출 계 (금융비 제외) | D25: =SUM(D22:D24) -> 91171596 | E25: =SUM(E22:E24) -> 2811440.5 | F25: =SUM(F22:F24) -> 2811440.5 | G25: =SUM(G22:G24) -> 2811440.5 | H25: =SUM(H22:H24) -> 2811440.5 | I25: =SUM(I22:I24) -> 2811440.5 | J25: =SUM(J22:J24) -> 2811440.5 | K25: =SUM(K22:K24) -> 2811440.5 | ... DY25: =SUM(DY22:DY24) -> 2728133.1
A27: 자금조달
B28: 기초 PF잔액 | D28: =0 -> 0 | E28: =D32 -> 0 | F28: =E32 -> 0 | G28: =F32 -> 0 | H28: =G32 -> 0 | I28: =H32 -> 0 | J28: =I32 -> 0 | K28: =J32 -> 0 | L28: =K32 -> 0 | ... DY28: =DX32 -> 5.2180826e+08
B29: 이자 (전월잔액×금리/12) | D29: =D28*'00_입력'!$C$30/12 -> 0 | E29: =E28*'00_입력'!$C$30/12 -> 0 | F29: =F28*'00_입력'!$C$30/12 -> 0 | G29: =G28*'00_입력'!$C$30/12 -> 0 | H29: =H28*'00_입력'!$C$30/12 -> 0 | I29: =I28*'00_입력'!$C$30/12 -> 0 | J29: =J28*'00_입력'!$C$30/12 -> 0 | K29: =K28*'00_입력'!$C$30/12 -> 0 | ... DY29: =DY28*'00_입력'!$C$30/12 -> 3630915.8 | DZ29: =SUM(D29:DY29) -> 79857157
B30: 상환 (적립계좌 재원) | D30: =MIN(D28,D19*'00_입력'!$C$42) -> 0 | E30: =MIN(E28,E19*'00_입력'!$C$42) -> 0 | F30: =MIN(F28,F19*'00_입력'!$C$42) -> 0 | G30: =MIN(G28,G19*'00_입력'!$C$42) -> 0 | H30: =MIN(H28,H19*'00_입력'!$C$42) -> 0 | I30: =MIN(I28,I19*'00_입력'!$C$42) -> 0 | J30: =MIN(J28,J19*'00_입력'!$C$42) -> 0 | K30: =MIN(K28,K19*'00_입력'!$C$42) -> 0 | ... DJ30: =MIN(DJ28,DJ19*'00_입력'!$C$42) -> 12901073 | DK30: =MIN(DK28,DK19*'00_입력'!$C$43) -> 10320853 | DL30: =MIN(DL28,DL19*'00_입력'!$C$43) -> 10320853 | DM30: =MIN(DM28,DM19*'00_입력'!$C$43) -> 10320853 | DN30: =MIN(DN28,DN19*'00_입력'!$C$43) -> 15481284 | DO30: =MIN(DO28,DO19*'00_입력'!$C$43) -> 15481284 | DP30: =MIN(DP28,DP19*'00_입력'!$C$43) -> 15481284 | DQ30: =MIN(DQ28,DQ19*'00_입력'!$C$43) -> 15481284 | DR30: =MIN(DR28,DR19*'00_입력'!$C$43) -> 15481284 | ... DY30: =MIN(DY28,DY19*'00_입력'!$C$43) -> 3.3174183e+08
B31: 인출 (부족액 자동) / Total열=피크 인출 | D31: =MAX(0,-('00_입력'!$C$28+D19-D25-D29-D30)) -> 0 | E31: =MAX(0,-(D33+E19-E25-E29-E30)) -> 0 | F31: =MAX(0,-(E33+F19-F25-F29-F30)) -> 0 | G31: =MAX(0,-(F33+G19-G25-G29-G30)) -> 0 | H31: =MAX(0,-(G33+H19-H25-H29-H30)) -> 0 | I31: =MAX(0,-(H33+I19-I25-I29-I30)) -> 0 | J31: =MAX(0,-(I33+J19-J25-J29-J30)) -> 0 | K31: =MAX(0,-(J33+K19-K25-K29-K30)) -> 0 | L31: =MAX(0,-(K33+L19-L25-L29-L30)) -> 0 | ... DY31: =MAX(0,-(DX33+DY19-DY25-DY29-DY30)) -> 6359048.9 | DZ31: =MAX(D31:DY31) -> 49005018
B32: 기말 PF잔액 | D32: =D28+D31-D30 -> 0 | E32: =E28+E31-E30 -> 0 | F32: =F28+F31-F30 -> 0 | G32: =G28+G31-G30 -> 0 | H32: =H28+H31-H30 -> 0 | I32: =I28+I31-I30 -> 0 | J32: =J28+J31-J30 -> 0 | K32: =K28+K31-K30 -> 0 | ... DY32: =DY28+DY31-DY30 -> 1.9642548e+08
B33: 현금 잔액 | D33: ='00_입력'!$C$28+D19-D25-D29+D31-D30 -> 2.549284e+08 | E33: =D33+E19-E25-E29+E31-E30 -> 2.5211696e+08 | F33: =E33+F19-F25-F29+F31-F30 -> 2.4930552e+08 | G33: =F33+G19-G25-G29+G31-G30 -> 2.4649408e+08 | H33: =G33+H19-H25-H29+H31-H30 -> 2.4368264e+08 | I33: =H33+I19-I25-I29+I31-I30 -> 2.408712e+08 | J33: =I33+J19-J25-J29+J31-J30 -> 2.3805976e+08 | K33: =J33+K19-K25-K29+K31-K30 -> 2.3524832e+08 | L33: =K33+L19-L25-L29+L31-L30 -> 2.3243688e+08 | ... DY33: =DX33+DY19-DY25-DY29+DY31-DY30 -> 0
B35: ★ 피크자금 소요 (PF잔액 최대) | C35: =MAX(D32:DY32) -> 5.3647116e+08
B36: 현금 최저점 (음수면 조달 부족) | C36: =MIN(D33:DY33) -> 0
B37: PF 한도 초과 여부 | C37: =IF(C35>('00_입력'!$C$29+'00_입력'!$C$32),"한도 초과","한도 내") -> 한도 내
B38: 총 금융비용 (이자 합계) | C38: =DZ29 -> 79857157

Sheet 03_민감도
A1: 민감도 분석
A3: 기준 사업이익 | B3: ='01_사업수지'!E77 -> -6.2801833e+08
A5: ■ 분양가 × 공사비 민감도 (사업이익, 천원)
A6: 분양가 \ 공사비 | B6: -10% | C6: +0% | D6: +10% | E6: +20%
A7: 분양가 +10% | B7: ='01_사업수지'!$E$13*(1+0.1)-('01_사업수지'!$H$71+'01_사업수지'!$H$41*-0.1) -> -4.036435e+08 | C7: ='01_사업수지'!$E$13*(1+0.1)-('01_사업수지'!$H$71+'01_사업수지'!$H$41*0) -> -5.1728073e+08 | D7: ='01_사업수지'!$E$13*(1+0.1)-('01_사업수지'!$H$71+'01_사업수지'!$H$41*0.1) -> -6.3091795e+08 | E7: ='01_사업수지'!$E$13*(1+0.1)-('01_사업수지'!$H$71+'01_사업수지'!$H$41*0.2) -> -7.4455518e+08
A8: 분양가 +0% | B8: ='01_사업수지'!$E$13*(1+0)-('01_사업수지'!$H$71+'01_사업수지'!$H$41*-0.1) -> -5.143811e+08 | C8: ='01_사업수지'!$E$13*(1+0)-('01_사업수지'!$H$71+'01_사업수지'!$H$41*0) -> -6.2801833e+08 | D8: ='01_사업수지'!$E$13*(1+0)-('01_사업수지'!$H$71+'01_사업수지'!$H$41*0.1) -> -7.4165555e+08 | E8: ='01_사업수지'!$E$13*(1+0)-('01_사업수지'!$H$71+'01_사업수지'!$H$41*0.2) -> -8.5529278e+08
A9: 분양가 -10% | B9: ='01_사업수지'!$E$13*(1+-0.1)-('01_사업수지'!$H$71+'01_사업수지'!$H$41*-0.1) -> -6.251187e+08 | C9: ='01_사업수지'!$E$13*(1+-0.1)-('01_사업수지'!$H$71+'01_사업수지'!$H$41*0) -> -7.3875593e+08 | D9: ='01_사업수지'!$E$13*(1+-0.1)-('01_사업수지'!$H$71+'01_사업수지'!$H$41*0.1) -> -8.5239315e+08 | E9: ='01_사업수지'!$E$13*(1+-0.1)-('01_사업수지'!$H$71+'01_사업수지'!$H$41*0.2) -> -9.6603038e+08
A11: ■ 손익분기
A12: 손익분기 분양률 | B12: =IFERROR('01_사업수지'!$H$71/'01_사업수지'!$E$13,0) -> 1.5671229 | C12: 총사업비 ÷ 총수입 — 이 비율만큼 팔려야 본전
A13: 손익분기 평당 분양가 | B13: =IFERROR('01_사업수지'!$H$71/'01_사업수지'!C11,0) -> 21170.574
A15: ■ 분양률 민감도 (회수 기준 사업이익, 천원)
A16: 분양률 | B16: 100% | C16: 90% | D16: 80% | E16: 70%
A17: 회수 수입 | B17: ='01_사업수지'!$E$13*1 -> 1107376000 | C17: ='01_사업수지'!$E$13*0.9 -> 996638400 | D17: ='01_사업수지'!$E$13*0.8 -> 885900800 | E17: ='01_사업수지'!$E$13*0.7 -> 775163200
A18: 사업이익 | B18: ='01_사업수지'!$E$13*1-'01_사업수지'!$H$71 -> -6.2801833e+08 | C18: ='01_사업수지'!$E$13*0.9-'01_사업수지'!$H$71 -> -7.3875593e+08 | D18: ='01_사업수지'!$E$13*0.8-'01_사업수지'!$H$71 -> -8.4949353e+08 | E18: ='01_사업수지'!$E$13*0.7-'01_사업수지'!$H$71 -> -9.6023113e+08
A20: ※ 공사비 단가가 [가정]이면 ±20% 구간을 반드시 검토하십시오.
A21: ※ 금리 민감도는 별도 표를 두지 않습니다. 00_입력 시트의 금리 셀을 바꾸면 02_현금흐름의 이자·PF잔액과 01_사업수지의 사업이익이 전부 재계산됩니다.
A22: ※ 분양률 민감도는 총액 기준 근사입니다. 회수 시점 변화는 02_현금흐름의 분양률 배열을 수정해 확인하십시오.

Sheet 04_요약
A1: 파주 축현리 도시개발사업 — 요약
A3: 항목 | B3: 값 | C3: 비고
A4: 사업유형 | B4: 민간 자체시행 — 도시개발사업(수용·사용방식)
A5: 소재지 | B5: 경기도 파주시 탄현면 축현리 608-5번지 일원
A6: 총 사업기간(개월) | B6: ='00_입력'!$C$24 -> 126 | C6: 지연 버퍼 포함
A7: 수입 총계 | B7: ='01_사업수지'!E13 -> 1107376000
A8: 지출 총계 | B8: ='01_사업수지'!H71 -> 1.7353943e+09
A9: 사업이익 | B9: ='01_사업수지'!E77 -> -6.2801833e+08
A10: 사업이익률 | B10: ='01_사업수지'!E78 -> -0.56712293
A11: 총 금융비용 | B11: ='02_현금흐름'!C38 -> 79857157 | C11: 월별 이자 합계
A12: 피크자금 소요 | B12: ='02_현금흐름'!C35 -> 5.3647116e+08 | C12: PF 잔액 최대치
A13: 현금 최저점 | B13: ='02_현금흐름'!C36 -> 0 | C13: 음수면 조달 부족
A14: PF 한도 초과 여부 | B14: ='02_현금흐름'!C37 -> 한도 내
A15: 손익분기 분양률 | B15: ='03_민감도'!B12 -> 1.5671229 | C15: 이 비율만큼 팔려야 본전
A16: LTV (대출한도/수입총계) | B16: =('00_입력'!$C$29+'00_입력'!$C$32)/'01_사업수지'!E13 -> 0.67005245
A17: LTC (대출한도/총사업비) | B17: =('00_입력'!$C$29+'00_입력'!$C$32)/'01_사업수지'!H71 -> 0.42756853

Sheet 05_검증
A1: 정합성 검증
A3: 검증 항목 | B3: 결과 | C3: 설명
A4: 자금집행 균형 (예산=기투입+필수+분양불+준공후불) | B4: ='01_사업수지'!H72 -> OK | C4: 불일치면 배분율 확인
A5: 사업이익 부호 | B5: =IF('01_사업수지'!E77>0,"흑자","적자") -> 적자 | C5: 적자면 재검토 판정 필요
A6: 현금 부족 발생 여부 | B6: =IF('02_현금흐름'!C36<0,"자금부족 발생","자금 충족") -> 자금 충족 | C6: 부족 시 추가 조달 방안 필수
A7: PF 한도 내 조달 가능 | B7: ='02_현금흐름'!C37 -> 한도 내 | C7: 초과 시 한도 증액 또는 자기자본 추가 필요
A8: 손익분기 분양률 < 100% | B8: =IF('03_민감도'!B12<1,"성립","사업 성립 불가") -> 사업 성립 불가 | C8: 100% 이상이면 팔아도 원가 회수 불가
A9: 수지표 수입 = 현금흐름 회수액 | B9: =IF(ROUND('02_현금흐름'!DZ19,0)>=ROUND('01_사업수지'!E11,0)-1,"일치","미회수 발생 — 분양률 누계 100% 미달") -> 일치 | C9: 사업기간 내 분양이 다 안 되면 수지표 수입은 과대
A11: ※ 02_현금흐름 시트의 '검증' 열에 '불일치'가 있으면 배분 로직을 점검하십시오.
